Workbook

Sheet 09.September Anlage
C4: inzig Schweißtechnik GmbH
A7: Name: | B7: Özcan Sezgin | D7: Nr. | G7: Monat: | H7: September
G9: VL Betrag:
G10: Vertragsnummer:
G11: BAV Betrag:
A12: Steuerfreie Auslöse: | C12: ='09.September Auslöse'!I42 -> 400
A14: Std. Lohn: | C14: ='09.September Lohn'!K40 -> 2164.5
A16: Fahr.Std.: | C16: ='09.September Lohn'!L40 -> 835.14286
A18: Nacht: | C18: ='09.September Lohn'!O40 -> 393.125 | D18: Samstag: | E18: ='09.September Lohn'!P40 -> 0 | F18: Sonntag 75%: | G18: ='09.September Lohn'!Q40 -> 0
A20: WBZ Std.: | C20: ='09.September Lohn'!N40 -> 0 | F20: Zulage SRE/SRZ | G20: ='09.September Lohn'!U40 -> 0
A22: Z SKV: | C22: ='09.September Lohn'!T40 -> 0 | F22: Zulage SKS | G22: ='09.September Lohn'!V40 -> 0
A24: Z SoW 5: | C24: ='09.September Lohn'!S40 -> 0 | F24: Höhenzu- lage | G24: ='09.September Lohn'!W40 -> 0
A26: Feiertag: | C26: ='09.September Lohn'!R40 -> 0
A28: Mängelbeseitigung:
A30: Telefon-Gutschrift: | C30: - | E30: Telefon-Abzug:
A32: Vorschuss Bank: | E32: Vorschuss Bar:
E34: Darlehen:
A36: Urlaub: | B36: Tage | C36: =COUNTIFS('09.September Lohn'!F8:F38,"urlaub",'09.September Lohn'!F8:F38,"Urlaub") -> 0
A38: Krank: | B38: Tage | C38: =COUNTIFS('09.September Lohn'!F8:F38,"Krank",'09.September Lohn'!F8:F38,"krank") -> 0
A41: AZK:
A43: Korrektur Vormonat: | C43: -
A46: Sonstiges:

Sheet 09.September Lohn
F1: inzig Schweißtechnik GmbH | CI1: Hinweise
CI2: Baustelle
B3: Dokumentation der Arbeitszeit | CI3: Urlaub = 8 std.
I4: =MONTH(1&H5) -> #VALUE! | CA4: 0.83333333 | CB4: : | CC4: 0.25 | CI4: AZK = 8 std.
C5: Name: | E5: Özcan Sezgin | H5: September | J5: 2026 | CI5: Krank = 8 Std.
K6: 18.5 | L6: =K6 -> 18.5 | M6: =K6 -> 18.5 | N6: =K6 -> 18.5 | O6: =K6/100*25 -> 4.625 | P6: =K6/100*25 -> 4.625 | Q6: =K6/100*75 -> 13.875 | R6: =K6 -> 18.5 | S6: 30 | T6: 30 | CI6: Urlaub 50% = 4 Std. (halber Tag)
A7: Tag | D7: Land | E7: Auftraggeber | F7: Baustelle | G7: Fahrer | H7: Arbeitszeit Von Bis | J7: Pause | K7: Arb.std. | L7: KM/FZ | M7: NL/LUX | N7: WBZ | O7: Na.25% | P7: Sa.25%ÜZ | Q7: So75% | R7: Fei.% | S7: Zulage SoW5 | T7: Zulage SKV | U7: Zulage SRE/SRZ | V7: Zulage SKS | W7: Höhenzu- lage | X7: Arbeits std. | BZ7: Feiertage | CI7: AZK 50% = 4 std. (halber Tag) Ausfall = 6 std. (Schichtausfall)
A8: =TEXT(B8,"TTT") -> #VALUE! | B8: =DATE(J5,I4,1) -> #VALUE! | C8: =IF(H8="","",IF(OR(H8>=0.708333333333333,H8<0.125),"N","")) | J8: =IF(ISBLANK(H8),"",IF(MOD(I8-H8,1)*24<9,0.5,IF(MOD(I8-H8,1)*24>12.5,1,0.75))) | K8: =IF(F8="Ausfall",6,IF(ISBLANK(H8),"",MOD(I8-H8,1)*24-J8)) | O8: =IFERROR(+MIN(IF(OR(H8="",I8=""),"",(MAX(,MIN(I8-(J8/24)+(H8>I8-(J8/24)),MAX(($CA$4>$CC$4),$CC$4))-MAX(H8,$CA$4))+MAX(,MIN(I8-(J8/24),MAX(($CA$4>$CC$4),$CC$4))-MAX(,$CA$4))*(H8>I8-(J8/24))+MAX(,MIN(I8-(J8/24)+(H8>I8-(J8/24)),MIN(($CA$4>$CC$4),$CC$4))-MAX(H8,))+MIN(I8-(J8/24),MIN(($CA$4>$CC$4),$CC$4))*(H8>I8-(J8/24)))*24),8),"") | P8: =IFERROR(IF(H8<0.0451388888888889,IF(AND(WEEKDAY(B9)>0,WEEKDAY(B9)<6),0,IF(AND(WEEKDAY(B9)=7,H8<BW8),K8/24,IF(AND(WEEKDAY(B9)=7,H8>BW8),"24:00"-H8,IF(AND(WEEKDAY(B9)=6,BW8>H8),0,BW8)))*24),IF(AND(WEEKDAY(B8)>0,WEEKDAY(B8)<6),0,IF(AND(WEEKDAY(B8)=7,BX8="",H8<BW8),K8/24,IF(AND(WEEKDAY(B8)=7,H8>BW8),"24:00"-H8,IF(AND(WEEKDAY(B8)=6,BX9="",BW8<H8),BW8,0)))*24)),"") | Q8: =IFERROR(IF(H8<0.0451388888888889,IF(AND(WEEKDAY(B9)>1,WEEKDAY(B9)<7),0,IF(AND(WEEKDAY(B9)=1,H8<BW8),K8/24,IF(AND(WEEKDAY(B9)=1,H8>BW8),"24:00"-H8,IF(AND(WEEKDAY(B9)=7,BW8>H8),0,BW8)))*24),IF(AND(WEEKDAY(B8)>1,WEEKDAY(B8)<7),0,IF(AND(WEEKDAY(B8)=1,BX8="",H8<BW8),K8/24,IF(AND(WEEKDAY(B8)=1,H8>BW8),"24:00"-H8,IF(AND(WEEKDAY(B8)=7,BX9="",BW8<H8),BW8,0)))*24)),"") | R8: =IFERROR(IF(AND(BX8="",BX9=""),"",IF(AND(BX8="x",BX9="x"),K8,IF(BX8="x",IF(H8>BW8,"24:00"-H8,BW8-H8)*24,IF(AND(BX9="x",H8>I8),BW8*24,"")))),"") | X8: =IFERROR(IF(OR(F8="Urlaub",F8="Krank",F8="AZK"),8,IF(OR(F8="Urlaub 50%",F8="AZK 50%"),4,IF(AND(F8="",BX8="x"),8,K8))),"") | BV8: =IF(L8="","",(L8/2-1)*2) | BW8: =IFERROR(I8-(J8/24),"") | BX8: =IF(ISERROR(VLOOKUP(B8,CB9:CB177,1,FALSE)),"","x") | CE8: Januar | CF8: 2020
A9: =TEXT(B9,"TTT") -> #VALUE! | B9: =B8+1 -> #VALUE! | C9: =IF(H9="","",IF(OR(H9>=0.708333333333333,H9<0.125),"N","")) | J9: =IF(ISBLANK(H9),"",IF(MOD(I9-H9,1)*24<9,0.5,IF(MOD(I9-H9,1)*24>12.5,1,0.75))) | K9: =IF(F9="Ausfall",6,IF(ISBLANK(H9),"",MOD(I9-H9,1)*24-J9)) | O9: =IFERROR(+MIN(IF(OR(H9="",I9=""),"",(MAX(,MIN(I9-(J9/24)+(H9>I9-(J9/24)),MAX(($CA$4>$CC$4),$CC$4))-MAX(H9,$CA$4))+MAX(,MIN(I9-(J9/24),MAX(($CA$4>$CC$4),$CC$4))-MAX(,$CA$4))*(H9>I9-(J9/24))+MAX(,MIN(I9-(J9/24)+(H9>I9-(J9/24)),MIN(($CA$4>$CC$4),$CC$4))-MAX(H9,))+MIN(I9-(J9/24),MIN(($CA$4>$CC$4),$CC$4))*(H9>I9-(J9/24)))*24),8),"") | P9: =IFERROR(IF(H9<0.0451388888888889,IF(AND(WEEKDAY(B10)>0,WEEKDAY(B10)<6),0,IF(AND(WEEKDAY(B10)=7,H9<BW9),K9/24,IF(AND(WEEKDAY(B10)=7,H9>BW9),"24:00"-H9,IF(AND(WEEKDAY(B10)=6,BW9>H9),0,BW9)))*24),IF(AND(WEEKDAY(B9)>0,WEEKDAY(B9)<6),0,IF(AND(WEEKDAY(B9)=7,BX9="",H9<BW9),K9/24,IF(AND(WEEKDAY(B9)=7,H9>BW9),"24:00"-H9,IF(AND(WEEKDAY(B9)=6,BX10="",BW9<H9),BW9,0)))*24)),"") | Q9: =IFERROR(IF(H9<0.0451388888888889,IF(AND(WEEKDAY(B10)>1,WEEKDAY(B10)<7),0,IF(AND(WEEKDAY(B10)=1,H9<BW9),K9/24,IF(AND(WEEKDAY(B10)=1,H9>BW9),"24:00"-H9,IF(AND(WEEKDAY(B10)=7,BW9>H9),0,BW9)))*24),IF(AND(WEEKDAY(B9)>1,WEEKDAY(B9)<7),0,IF(AND(WEEKDAY(B9)=1,BX9="",H9<BW9),K9/24,IF(AND(WEEKDAY(B9)=1,H9>BW9),"24:00"-H9,IF(AND(WEEKDAY(B9)=7,BX10="",BW9<H9),BW9,0)))*24)),"") | R9: =IFERROR(IF(AND(BX9="",BX10=""),"",IF(AND(BX9="x",BX10="x"),K9,IF(BX9="x",IF(H9>BW9,"24:00"-H9,BW9-H9)*24,IF(AND(BX10="x",H9>I9),BW9*24,"")))),"") | X9: =IFERROR(IF(OR(F9="Urlaub",F9="Krank",F9="AZK"),8,IF(OR(F9="Urlaub 50%",F9="AZK 50%"),4,IF(AND(F9="",BX9="x"),8,K9))),"") | BV9: =IF(L9="","",(L9/2-1)*2) | BW9: =IFERROR(I9-(J9/24),"") | BX9: =IF(ISERROR(VLOOKUP(B9,CB9:CB177,1,FALSE)),"","x") | BZ9: Neujahr | CB9: 43466 | CE9: Februar | CF9: 2021
A10: =TEXT(B10,"TTT") -> #VALUE! | B10: =B9+1 -> #VALUE! | C10: =IF(H10="","",IF(OR(H10>=0.708333333333333,H10<0.125),"N","")) | J10: =IF(ISBLANK(H10),"",IF(MOD(I10-H10,1)*24<9,0.5,IF(MOD(I10-H10,1)*24>12.5,1,0.75))) | K10: =IF(F10="Ausfall",6,IF(ISBLANK(H10),"",MOD(I10-H10,1)*24-J10)) | O10: =IFERROR(+MIN(IF(OR(H10="",I10=""),"",(MAX(,MIN(I10-(J10/24)+(H10>I10-(J10/24)),MAX(($CA$4>$CC$4),$CC$4))-MAX(H10,$CA$4))+MAX(,MIN(I10-(J10/24),MAX(($CA$4>$CC$4),$CC$4))-MAX(,$CA$4))*(H10>I10-(J10/24))+MAX(,MIN(I10-(J10/24)+(H10>I10-(J10/24)),MIN(($CA$4>$CC$4),$CC$4))-MAX(H10,))+MIN(I10-(J10/24),MIN(($CA$4>$CC$4),$CC$4))*(H10>I10-(J10/24)))*24),8),"") | P10: =IFERROR(IF(H10<0.0451388888888889,IF(AND(WEEKDAY(B11)>0,WEEKDAY(B11)<6),0,IF(AND(WEEKDAY(B11)=7,H10<BW10),K10/24,IF(AND(WEEKDAY(B11)=7,H10>BW10),"24:00"-H10,IF(AND(WEEKDAY(B11)=6,BW10>H10),0,BW10)))*24),IF(AND(WEEKDAY(B10)>0,WEEKDAY(B10)<6),0,IF(AND(WEEKDAY(B10)=7,BX10="",H10<BW10),K10/24,IF(AND(WEEKDAY(B10)=7,H10>BW10),"24:00"-H10,IF(AND(WEEKDAY(B10)=6,BX11="",BW10<H10),BW10,0)))*24)),"") | Q10: =IFERROR(IF(H10<0.0451388888888889,IF(AND(WEEKDAY(B11)>1,WEEKDAY(B11)<7),0,IF(AND(WEEKDAY(B11)=1,H10<BW10),K10/24,IF(AND(WEEKDAY(B11)=1,H10>BW10),"24:00"-H10,IF(AND(WEEKDAY(B11)=7,BW10>H10),0,BW10)))*24),IF(AND(WEEKDAY(B10)>1,WEEKDAY(B10)<7),0,IF(AND(WEEKDAY(B10)=1,BX10="",H10<BW10),K10/24,IF(AND(WEEKDAY(B10)=1,H10>BW10),"24:00"-H10,IF(AND(WEEKDAY(B10)=7,BX11="",BW10<H10),BW10,0)))*24)),"") | R10: =IFERROR(IF(AND(BX10="",BX11=""),"",IF(AND(BX10="x",BX11="x"),K10,IF(BX10="x",IF(H10>BW10,"24:00"-H10,BW10-H10)*24,IF(AND(BX11="x",H10>I10),BW10*24,"")))),"") | X10: =IFERROR(IF(OR(F10="Urlaub",F10="Krank",F10="AZK"),8,IF(OR(F10="Urlaub 50%",F10="AZK 50%"),4,IF(AND(F10="",BX10="x"),8,K10))),"") | BV10: =IF(L10="","",(L10/2-1)*2) | BW10: =IFERROR(I10-(J10/24),"") | BX10: =IF(ISERROR(VLOOKUP(B10,CB9:CB177,1,FALSE)),"","x") | BZ10: Karfreitag | CB10: 43574 | CE10: März | CF10: 2022
A11: =TEXT(B11,"TTT") -> #VALUE! | B11: =B10+1 -> #VALUE! | C11: =IF(H11="","",IF(OR(H11>=0.708333333333333,H11<0.125),"N","")) | E11: Hoffnungsthal | F11: An-Abfarth | G11: Fahrer Privat Auto | H11: 0.29166667 | I11: 0.73958333 | J11: =IF(ISBLANK(H11),"",IF(MOD(I11-H11,1)*24<9,0.5,IF(MOD(I11-H11,1)*24>12.5,1,0.75))) -> 0.75 | K11: =IF(F11="Ausfall",6,IF(ISBLANK(H11),"",MOD(I11-H11,1)*24-J11)) -> 10 | L11: 280 | O11: =IFERROR(+MIN(IF(OR(H11="",I11=""),"",(MAX(,MIN(I11-(J11/24)+(H11>I11-(J11/24)),MAX(($CA$4>$CC$4),$CC$4))-MAX(H11,$CA$4))+MAX(,MIN(I11-(J11/24),MAX(($CA$4>$CC$4),$CC$4))-MAX(,$CA$4))*(H11>I11-(J11/24))+MAX(,MIN(I11-(J11/24)+(H11>I11-(J11/24)),MIN(($CA$4>$CC$4),$CC$4))-MAX(H11,))+MIN(I11-(J11/24),MIN(($CA$4>$CC$4),$CC$4))*(H11>I11-(J11/24)))*24),8),"") -> 0 | P11: =IFERROR(IF(H11<0.0451388888888889,IF(AND(WEEKDAY(B12)>0,WEEKDAY(B12)<6),0,IF(AND(WEEKDAY(B12)=7,H11<BW11),K11/24,IF(AND(WEEKDAY(B12)=7,H11>BW11),"24:00"-H11,IF(AND(WEEKDAY(B12)=6,BW11>H11),0,BW11)))*24),IF(AND(WEEKDAY(B11)>0,WEEKDAY(B11)<6),0,IF(AND(WEEKDAY(B11)=7,BX11="",H11<BW11),K11/24,IF(AND(WEEKDAY(B11)=7,H11>BW11),"24:00"-H11,IF(AND(WEEKDAY(B11)=6,BX12="",BW11<H11),BW11,0)))*24)),"") | Q11: =IFERROR(IF(H11<0.0451388888888889,IF(AND(WEEKDAY(B12)>1,WEEKDAY(B12)<7),0,IF(AND(WEEKDAY(B12)=1,H11<BW11),K11/24,IF(AND(WEEKDAY(B12)=1,H11>BW11),"24:00"-H11,IF(AND(WEEKDAY(B12)=7,BW11>H11),0,BW11)))*24),IF(AND(WEEKDAY(B11)>1,WEEKDAY(B11)<7),0,IF(AND(WEEKDAY(B11)=1,BX11="",H11<BW11),K11/24,IF(AND(WEEKDAY(B11)=1,H11>BW11),"24:00"-H11,IF(AND(WEEKDAY(B11)=7,BX12="",BW11<H11),BW11,0)))*24)),"") | R11: =IFERROR(IF(AND(BX11="",BX12=""),"",IF(AND(BX11="x",BX12="x"),K11,IF(BX11="x",IF(H11>BW11,"24:00"-H11,BW11-H11)*24,IF(AND(BX12="x",H11>I11),BW11*24,"")))),"") | X11: =IFERROR(IF(OR(F11="Urlaub",F11="Krank",F11="AZK"),8,IF(OR(F11="Urlaub 50%",F11="AZK 50%"),4,IF(AND(F11="",BX11="x"),8,K11))),"") -> 10 | BV11: =IF(L11="","",(L11/2-1)*2) -> 278 | BW11: =IFERROR(I11-(J11/24),"") -> 0.70833333 | BX11: =IF(ISERROR(VLOOKUP(B11,CB9:CB177,1,FALSE)),"","x") | BZ11: Ostersonntag | CB11: 43576 | CE11: April | CF11: 2023
A12: =TEXT(B12,"TTT") -> #VALUE! | B12: =B11+1 -> #VALUE! | C12: =IF(H12="","",IF(OR(H12>=0.708333333333333,H12<0.125),"N","")) | J12: =IF(ISBLANK(H12),"",IF(MOD(I12-H12,1)*24<9,0.5,IF(MOD(I12-H12,1)*24>12.5,1,0.75))) | K12: =IF(F12="Ausfall",6,IF(ISBLANK(H12),"",MOD(I12-H12,1)*24-J12)) | O12: =IFERROR(+MIN(IF(OR(H12="",I12=""),"",(MAX(,MIN(I12-(J12/24)+(H12>I12-(J12/24)),MAX(($CA$4>$CC$4),$CC$4))-MAX(H12,$CA$4))+MAX(,MIN(I12-(J12/24),MAX(($CA$4>$CC$4),$CC$4))-MAX(,$CA$4))*(H12>I12-(J12/24))+MAX(,MIN(I12-(J12/24)+(H12>I12-(J12/24)),MIN(($CA$4>$CC$4),$CC$4))-MAX(H12,))+MIN(I12-(J12/24),MIN(($CA$4>$CC$4),$CC$4))*(H12>I12-(J12/24)))*24),8),"") | P12: =IFERROR(IF(H12<0.0451388888888889,IF(AND(WEEKDAY(B13)>0,WEEKDAY(B13)<6),0,IF(AND(WEEKDAY(B13)=7,H12<BW12),K12/24,IF(AND(WEEKDAY(B13)=7,H12>BW12),"24:00"-H12,IF(AND(WEEKDAY(B13)=6,BW12>H12),0,BW12)))*24),IF(AND(WEEKDAY(B12)>0,WEEKDAY(B12)<6),0,IF(AND(WEEKDAY(B12)=7,BX12="",H12<BW12),K12/24,IF(AND(WEEKDAY(B12)=7,H12>BW12),"24:00"-H12,IF(AND(WEEKDAY(B12)=6,BX13="",BW12<H12),BW12,0)))*24)),"") | Q12: =IFERROR(IF(H12<0.0451388888888889,IF(AND(WEEKDAY(B13)>1,WEEKDAY(B13)<7),0,IF(AND(WEEKDAY(B13)=1,H12<BW12),K12/24,IF(AND(WEEKDAY(B13)=1,H12>BW12),"24:00"-H12,IF(AND(WEEKDAY(B13)=7,BW12>H12),0,BW12)))*24),IF(AND(WEEKDAY(B12)>1,WEEKDAY(B12)<7),0,IF(AND(WEEKDAY(B12)=1,BX12="",H12<BW12),K12/24,IF(AND(WEEKDAY(B12)=1,H12>BW12),"24:00"-H12,IF(AND(WEEKDAY(B12)=7,BX13="",BW12<H12),BW12,0)))*24)),"") | R12: =IFERROR(IF(AND(BX12="",BX13=""),"",IF(AND(BX12="x",BX13="x"),K12,IF(BX12="x",IF(H12>BW12,"24:00"-H12,BW12-H12)*24,IF(AND(BX13="x",H12>I12),BW12*24,"")))),"") | X12: =IFERROR(IF(OR(F12="Urlaub",F12="Krank",F12="AZK"),8,IF(OR(F12="Urlaub 50%",F12="AZK 50%"),4,IF(AND(F12="",BX12="x"),8,K12))),"") | BV12: =IF(L12="","",(L12/2-1)*2) | BW12: =IFERROR(I12-(J12/24),"") | BX12: =IF(ISERROR(VLOOKUP(B12,CB9:CB177,1,FALSE)),"","x") | BZ12: Ostermontag | CB12: 43577 | CE12: Mai | CF12: 2024
A13: =TEXT(B13,"TTT") -> #VALUE! | B13: =B12+1 -> #VALUE! | C13: =IF(H13="","",IF(OR(H13>=0.708333333333333,H13<0.125),"N","")) | J13: =IF(ISBLANK(H13),"",IF(MOD(I13-H13,1)*24<9,0.5,IF(MOD(I13-H13,1)*24>12.5,1,0.75))) | K13: =IF(F13="Ausfall",6,IF(ISBLANK(H13),"",MOD(I13-H13,1)*24-J13)) | O13: =IFERROR(+MIN(IF(OR(H13="",I13=""),"",(MAX(,MIN(I13-(J13/24)+(H13>I13-(J13/24)),MAX(($CA$4>$CC$4),$CC$4))-MAX(H13,$CA$4))+MAX(,MIN(I13-(J13/24),MAX(($CA$4>$CC$4),$CC$4))-MAX(,$CA$4))*(H13>I13-(J13/24))+MAX(,MIN(I13-(J13/24)+(H13>I13-(J13/24)),MIN(($CA$4>$CC$4),$CC$4))-MAX(H13,))+MIN(I13-(J13/24),MIN(($CA$4>$CC$4),$CC$4))*(H13>I13-(J13/24)))*24),8),"") | P13: =IFERROR(IF(H13<0.0451388888888889,IF(AND(WEEKDAY(B14)>0,WEEKDAY(B14)<6),0,IF(AND(WEEKDAY(B14)=7,H13<BW13),K13/24,IF(AND(WEEKDAY(B14)=7,H13>BW13),"24:00"-H13,IF(AND(WEEKDAY(B14)=6,BW13>H13),0,BW13)))*24),IF(AND(WEEKDAY(B13)>0,WEEKDAY(B13)<6),0,IF(AND(WEEKDAY(B13)=7,BX13="",H13<BW13),K13/24,IF(AND(WEEKDAY(B13)=7,H13>BW13),"24:00"-H13,IF(AND(WEEKDAY(B13)=6,BX14="",BW13<H13),BW13,0)))*24)),"") | Q13: =IFERROR(IF(H13<0.0451388888888889,IF(AND(WEEKDAY(B14)>1,WEEKDAY(B14)<7),0,IF(AND(WEEKDAY(B14)=1,H13<BW13),K13/24,IF(AND(WEEKDAY(B14)=1,H13>BW13),"24:00"-H13,IF(AND(WEEKDAY(B14)=7,BW13>H13),0,BW13)))*24),IF(AND(WEEKDAY(B13)>1,WEEKDAY(B13)<7),0,IF(AND(WEEKDAY(B13)=1,BX13="",H13<BW13),K13/24,IF(AND(WEEKDAY(B13)=1,H13>BW13),"24:00"-H13,IF(AND(WEEKDAY(B13)=7,BX14="",BW13<H13),BW13,0)))*24)),"") | R13: =IFERROR(IF(AND(BX13="",BX14=""),"",IF(AND(BX13="x",BX14="x"),K13,IF(BX13="x",IF(H13>BW13,"24:00"-H13,BW13-H13)*24,IF(AND(BX14="x",H13>I13),BW13*24,"")))),"") | X13: =IFERROR(IF(OR(F13="Urlaub",F13="Krank",F13="AZK"),8,IF(OR(F13="Urlaub 50%",F13="AZK 50%"),4,IF(AND(F13="",BX13="x"),8,K13))),"") | BV13: =IF(L13="","",(L13/2-1)*2) | BW13: =IFERROR(I13-(J13/24),"") | BX13: =IF(ISERROR(VLOOKUP(B13,CB9:CB177,1,FALSE)),"","x") | BZ13: Tag der Arbeit | CB13: 43586 | CE13: Juni | CF13: 2025
A14: =TEXT(B14,"TTT") -> #VALUE! | B14: =B13+1 -> #VALUE! | C14: =IF(H14="","",IF(OR(H14>=0.708333333333333,H14<0.125),"N","")) | E14: Unkel | F14: An-Abfarth | H14: 0.29166667 | I14: 0.78125 | J14: =IF(ISBLANK(H14),"",IF(MOD(I14-H14,1)*24<9,0.5,IF(MOD(I14-H14,1)*24>12.5,1,0.75))) -> 0.75 | K14: =IF(F14="Ausfall",6,IF(ISBLANK(H14),"",MOD(I14-H14,1)*24-J14)) -> 11 | L14: 160 | O14: =IFERROR(+MIN(IF(OR(H14="",I14=""),"",(MAX(,MIN(I14-(J14/24)+(H14>I14-(J14/24)),MAX(($CA$4>$CC$4),$CC$4))-MAX(H14,$CA$4))+MAX(,MIN(I14-(J14/24),MAX(($CA$4>$CC$4),$CC$4))-MAX(,$CA$4))*(H14>I14-(J14/24))+MAX(,MIN(I14-(J14/24)+(H14>I14-(J14/24)),MIN(($CA$4>$CC$4),$CC$4))-MAX(H14,))+MIN(I14-(J14/24),MIN(($CA$4>$CC$4),$CC$4))*(H14>I14-(J14/24)))*24),8),"") -> 0 | P14: =IFERROR(IF(H14<0.0451388888888889,IF(AND(WEEKDAY(B15)>0,WEEKDAY(B15)<6),0,IF(AND(WEEKDAY(B15)=7,H14<BW14),K14/24,IF(AND(WEEKDAY(B15)=7,H14>BW14),"24:00"-H14,IF(AND(WEEKDAY(B15)=6,BW14>H14),0,BW14)))*24),IF(AND(WEEKDAY(B14)>0,WEEKDAY(B14)<6),0,IF(AND(WEEKDAY(B14)=7,BX14="",H14<BW14),K14/24,IF(AND(WEEKDAY(B14)=7,H14>BW14),"24:00"-H14,IF(AND(WEEKDAY(B14)=6,BX15="",BW14<H14),BW14,0)))*24)),"") | Q14: =IFERROR(IF(H14<0.0451388888888889,IF(AND(WEEKDAY(B15)>1,WEEKDAY(B15)<7),0,IF(AND(WEEKDAY(B15)=1,H14<BW14),K14/24,IF(AND(WEEKDAY(B15)=1,H14>BW14),"24:00"-H14,IF(AND(WEEKDAY(B15)=7,BW14>H14),0,BW14)))*24),IF(AND(WEEKDAY(B14)>1,WEEKDAY(B14)<7),0,IF(AND(WEEKDAY(B14)=1,BX14="",H14<BW14),K14/24,IF(AND(WEEKDAY(B14)=1,H14>BW14),"24:00"-H14,IF(AND(WEEKDAY(B14)=7,BX15="",BW14<H14),BW14,0)))*24)),"") | R14: =IFERROR(IF(AND(BX14="",BX15=""),"",IF(AND(BX14="x",BX15="x"),K14,IF(BX14="x",IF(H14>BW14,"24:00"-H14,BW14-H14)*24,IF(AND(BX15="x",H14>I14),BW14*24,"")))),"") | X14: =IFERROR(IF(OR(F14="Urlaub",F14="Krank",F14="AZK"),8,IF(OR(F14="Urlaub 50%",F14="AZK 50%"),4,IF(AND(F14="",BX14="x"),8,K14))),"") -> 11 | BV14: =IF(L14="","",(L14/2-1)*2) -> 158 | BW14: =IFERROR(I14-(J14/24),"") -> 0.75 | BX14: =IF(ISERROR(VLOOKUP(B14,CB9:CB177,1,FALSE)),"","x") | BZ14: Christi Himmelfahrt | CB14: 43615 | CE14: Juli | CF14: 2026
A15: =TEXT(B15,"TTT") -> #VALUE! | B15: =B14+1 -> #VALUE! | C15: =IF(H15="","",IF(OR(H15>=0.708333333333333,H15<0.125),"N","")) -> N | E15: Wiesau | F15: Anfarth | H15: 0.91666667 | I15: 0.40625 | J15: =IF(ISBLANK(H15),"",IF(MOD(I15-H15,1)*24<9,0.5,IF(MOD(I15-H15,1)*24>12.5,1,0.75))) -> 0.75 | K15: =IF(F15="Ausfall",6,IF(ISBLANK(H15),"",MOD(I15-H15,1)*24-J15)) -> 11 | L15: 510 | O15: =IFERROR(+MIN(IF(OR(H15="",I15=""),"",(MAX(,MIN(I15-(J15/24)+(H15>I15-(J15/24)),MAX(($CA$4>$CC$4),$CC$4))-MAX(H15,$CA$4))+MAX(,MIN(I15-(J15/24),MAX(($CA$4>$CC$4),$CC$4))-MAX(,$CA$4))*(H15>I15-(J15/24))+MAX(,MIN(I15-(J15/24)+(H15>I15-(J15/24)),MIN(($CA$4>$CC$4),$CC$4))-MAX(H15,))+MIN(I15-(J15/24),MIN(($CA$4>$CC$4),$CC$4))*(H15>I15-(J15/24)))*24),8),"") -> 8 | P15: =IFERROR(IF(H15<0.0451388888888889,IF(AND(WEEKDAY(B16)>0,WEEKDAY(B16)<6),0,IF(AND(WEEKDAY(B16)=7,H15<BW15),K15/24,IF(AND(WEEKDAY(B16)=7,H15>BW15),"24:00"-H15,IF(AND(WEEKDAY(B16)=6,BW15>H15),0,BW15)))*24),IF(AND(WEEKDAY(B15)>0,WEEKDAY(B15)<6),0,IF(AND(WEEKDAY(B15)=7,BX15="",H15<BW15),K15/24,IF(AND(WEEKDAY(B15)=7,H15>BW15),"24:00"-H15,IF(AND(WEEKDAY(B15)=6,BX16="",BW15<H15),BW15,0)))*24)),"") | Q15: =IFERROR(IF(H15<0.0451388888888889,IF(AND(WEEKDAY(B16)>1,WEEKDAY(B16)<7),0,IF(AND(WEEKDAY(B16)=1,H15<BW15),K15/24,IF(AND(WEEKDAY(B16)=1,H15>BW15),"24:00"-H15,IF(AND(WEEKDAY(B16)=7,BW15>H15),0,BW15)))*24),IF(AND(WEEKDAY(B15)>1,WEEKDAY(B15)<7),0,IF(AND(WEEKDAY(B15)=1,BX15="",H15<BW15),K15/24,IF(AND(WEEKDAY(B15)=1,H15>BW15),"24:00"-H15,IF(AND(WEEKDAY(B15)=7,BX16="",BW15<H15),BW15,0)))*24)),"") | R15: =IFERROR(IF(AND(BX15="",BX16=""),"",IF(AND(BX15="x",BX16="x"),K15,IF(BX15="x",IF(H15>BW15,"24:00"-H15,BW15-H15)*24,IF(AND(BX16="x",H15>I15),BW15*24,"")))),"") | X15: =IFERROR(IF(OR(F15="Urlaub",F15="Krank",F15="AZK"),8,IF(OR(F15="Urlaub 50%",F15="AZK 50%"),4,IF(AND(F15="",BX15="x"),8,K15))),"") -> 11 | BV15: =IF(L15="","",(L15/2-1)*2) -> 508 | BW15: =IFERROR(I15-(J15/24),"") -> 0.375 | BX15: =IF(ISERROR(VLOOKUP(B15,CB9:CB177,1,FALSE)),"","x") | BZ15: Pfingstsonntag | CB15: 43625 | CE15: August | CF15: 2027
A16: =TEXT(B16,"TTT") -> #VALUE! | B16: =B15+1 -> #VALUE! | C16: =IF(H16="","",IF(OR(H16>=0.708333333333333,H16<0.125),"N","")) -> N | E16: Wiesau | H16: 0.95833333 | I16: 0.36458333 | J16: =IF(ISBLANK(H16),"",IF(MOD(I16-H16,1)*24<9,0.5,IF(MOD(I16-H16,1)*24>12.5,1,0.75))) -> 0.75 | K16: =IF(F16="Ausfall",6,IF(ISBLANK(H16),"",MOD(I16-H16,1)*24-J16)) -> 9 | O16: =IFERROR(+MIN(IF(OR(H16="",I16=""),"",(MAX(,MIN(I16-(J16/24)+(H16>I16-(J16/24)),MAX(($CA$4>$CC$4),$CC$4))-MAX(H16,$CA$4))+MAX(,MIN(I16-(J16/24),MAX(($CA$4>$CC$4),$CC$4))-MAX(,$CA$4))*(H16>I16-(J16/24))+MAX(,MIN(I16-(J16/24)+(H16>I16-(J16/24)),MIN(($CA$4>$CC$4),$CC$4))-MAX(H16,))+MIN(I16-(J16/24),MIN(($CA$4>$CC$4),$CC$4))*(H16>I16-(J16/24)))*24),8),"") -> 7 | P16: =IFERROR(IF(H16<0.0451388888888889,IF(AND(WEEKDAY(B17)>0,WEEKDAY(B17)<6),0,IF(AND(WEEKDAY(B17)=7,H16<BW16),K16/24,IF(AND(WEEKDAY(B17)=7,H16>BW16),"24:00"-H16,IF(AND(WEEKDAY(B17)=6,BW16>H16),0,BW16)))*24),IF(AND(WEEKDAY(B16)>0,WEEKDAY(B16)<6),0,IF(AND(WEEKDAY(B16)=7,BX16="",H16<BW16),K16/24,IF(AND(WEEKDAY(B16)=7,H16>BW16),"24:00"-H16,IF(AND(WEEKDAY(B16)=6,BX17="",BW16<H16),BW16,0)))*24)),"") | Q16: =IFERROR(IF(H16<0.0451388888888889,IF(AND(WEEKDAY(B17)>1,WEEKDAY(B17)<7),0,IF(AND(WEEKDAY(B17)=1,H16<BW16),K16/24,IF(AND(WEEKDAY(B17)=1,H16>BW16),"24:00"-H16,IF(AND(WEEKDAY(B17)=7,BW16>H16),0,BW16)))*24),IF(AND(WEEKDAY(B16)>1,WEEKDAY(B16)<7),0,IF(AND(WEEKDAY(B16)=1,BX16="",H16<BW16),K16/24,IF(AND(WEEKDAY(B16)=1,H16>BW16),"24:00"-H16,IF(AND(WEEKDAY(B16)=7,BX17="",BW16<H16),BW16,0)))*24)),"") | R16: =IFERROR(IF(AND(BX16="",BX17=""),"",IF(AND(BX16="x",BX17="x"),K16,IF(BX16="x",IF(H16>BW16,"24:00"-H16,BW16-H16)*24,IF(AND(BX17="x",H16>I16),BW16*24,"")))),"") | X16: =IFERROR(IF(OR(F16="Urlaub",F16="Krank",F16="AZK"),8,IF(OR(F16="Urlaub 50%",F16="AZK 50%"),4,IF(AND(F16="",BX16="x"),8,K16))),"") -> 9 | BV16: =IF(L16="","",(L16/2-1)*2) | BW16: =IFERROR(I16-(J16/24),"") -> 0.33333333 | BX16: =IF(ISERROR(VLOOKUP(B16,CB9:CB177,1,FALSE)),"","x") | BZ16: Pfingstmontag | CB16: 43626 | CE16: September | CF16: 2028
A17: =TEXT(B17,"TTT") -> #VALUE! | B17: =B16+1 -> #VALUE! | C17: =IF(H17="","",IF(OR(H17>=0.708333333333333,H17<0.125),"N","")) -> N | E17: Wiesau | H17: 0.83333333 | I17: 0.28125 | J17: =IF(ISBLANK(H17),"",IF(MOD(I17-H17,1)*24<9,0.5,IF(MOD(I17-H17,1)*24>12.5,1,0.75))) -> 0.75 | K17: =IF(F17="Ausfall",6,IF(ISBLANK(H17),"",MOD(I17-H17,1)*24-J17)) -> 10 | O17: =IFERROR(+MIN(IF(OR(H17="",I17=""),"",(MAX(,MIN(I17-(J17/24)+(H17>I17-(J17/24)),MAX(($CA$4>$CC$4),$CC$4))-MAX(H17,$CA$4))+MAX(,MIN(I17-(J17/24),MAX(($CA$4>$CC$4),$CC$4))-MAX(,$CA$4))*(H17>I17-(J17/24))+MAX(,MIN(I17-(J17/24)+(H17>I17-(J17/24)),MIN(($CA$4>$CC$4),$CC$4))-MAX(H17,))+MIN(I17-(J17/24),MIN(($CA$4>$CC$4),$CC$4))*(H17>I17-(J17/24)))*24),8),"") -> 8 | P17: =IFERROR(IF(H17<0.0451388888888889,IF(AND(WEEKDAY(B18)>0,WEEKDAY(B18)<6),0,IF(AND(WEEKDAY(B18)=7,H17<BW17),K17/24,IF(AND(WEEKDAY(B18)=7,H17>BW17),"24:00"-H17,IF(AND(WEEKDAY(B18)=6,BW17>H17),0,BW17)))*24),IF(AND(WEEKDAY(B17)>0,WEEKDAY(B17)<6),0,IF(AND(WEEKDAY(B17)=7,BX17="",H17<BW17),K17/24,IF(AND(WEEKDAY(B17)=7,H17>BW17),"24:00"-H17,IF(AND(WEEKDAY(B17)=6,BX18="",BW17<H17),BW17,0)))*24)),"") | Q17: =IFERROR(IF(H17<0.0451388888888889,IF(AND(WEEKDAY(B18)>1,WEEKDAY(B18)<7),0,IF(AND(WEEKDAY(B18)=1,H17<BW17),K17/24,IF(AND(WEEKDAY(B18)=1,H17>BW17),"24:00"-H17,IF(AND(WEEKDAY(B18)=7,BW17>H17),0,BW17)))*24),IF(AND(WEEKDAY(B17)>1,WEEKDAY(B17)<7),0,IF(AND(WEEKDAY(B17)=1,BX17="",H17<BW17),K17/24,IF(AND(WEEKDAY(B17)=1,H17>BW17),"24:00"-H17,IF(AND(WEEKDAY(B17)=7,BX18="",BW17<H17),BW17,0)))*24)),"") | R17: =IFERROR(IF(AND(BX17="",BX18=""),"",IF(AND(BX17="x",BX18="x"),K17,IF(BX17="x",IF(H17>BW17,"24:00"-H17,BW17-H17)*24,IF(AND(BX18="x",H17>I17),BW17*24,"")))),"") | X17: =IFERROR(IF(OR(F17="Urlaub",F17="Krank",F17="AZK"),8,IF(OR(F17="Urlaub 50%",F17="AZK 50%"),4,IF(AND(F17="",BX17="x"),8,K17))),"") -> 10 | BV17: =IF(L17="","",(L17/2-1)*2) | BW17: =IFERROR(I17-(J17/24),"") -> 0.25 | BX17: =IF(ISERROR(VLOOKUP(B17,CB9:CB177,1,FALSE)),"","x") | BZ17: Fronleichnam | CB17: 43636 | CE17: Oktober | CF17: 2029
A18: =TEXT(B18,"TTT") -> #VALUE! | B18: =B17+1 -> #VALUE! | C18: =IF(H18="","",IF(OR(H18>=0.708333333333333,H18<0.125),"N","")) -> N | E18: Wiesau | H18: 0.83333333 | I18: 0.1875 | J18: =IF(ISBLANK(H18),"",IF(MOD(I18-H18,1)*24<9,0.5,IF(MOD(I18-H18,1)*24>12.5,1,0.75))) -> 0.5 | K18: =IF(F18="Ausfall",6,IF(ISBLANK(H18),"",MOD(I18-H18,1)*24-J18)) -> 8 | O18: =IFERROR(+MIN(IF(OR(H18="",I18=""),"",(MAX(,MIN(I18-(J18/24)+(H18>I18-(J18/24)),MAX(($CA$4>$CC$4),$CC$4))-MAX(H18,$CA$4))+MAX(,MIN(I18-(J18/24),MAX(($CA$4>$CC$4),$CC$4))-MAX(,$CA$4))*(H18>I18-(J18/24))+MAX(,MIN(I18-(J18/24)+(H18>I18-(J18/24)),MIN(($CA$4>$CC$4),$CC$4))-MAX(H18,))+MIN(I18-(J18/24),MIN(($CA$4>$CC$4),$CC$4))*(H18>I18-(J18/24)))*24),8),"") -> 8 | P18: =IFERROR(IF(H18<0.0451388888888889,IF(AND(WEEKDAY(B19)>0,WEEKDAY(B19)<6),0,IF(AND(WEEKDAY(B19)=7,H18<BW18),K18/24,IF(AND(WEEKDAY(B19)=7,H18>BW18),"24:00"-H18,IF(AND(WEEKDAY(B19)=6,BW18>H18),0,BW18)))*24),IF(AND(WEEKDAY(B18)>0,WEEKDAY(B18)<6),0,IF(AND(WEEKDAY(B18)=7,BX18="",H18<BW18),K18/24,IF(AND(WEEKDAY(B18)=7,H18>BW18),"24:00"-H18,IF(AND(WEEKDAY(B18)=6,BX19="",BW18<H18),BW18,0)))*24)),"") | Q18: =IFERROR(IF(H18<0.0451388888888889,IF(AND(WEEKDAY(B19)>1,WEEKDAY(B19)<7),0,IF(AND(WEEKDAY(B19)=1,H18<BW18),K18/24,IF(AND(WEEKDAY(B19)=1,H18>BW18),"24:00"-H18,IF(AND(WEEKDAY(B19)=7,BW18>H18),0,BW18)))*24),IF(AND(WEEKDAY(B18)>1,WEEKDAY(B18)<7),0,IF(AND(WEEKDAY(B18)=1,BX18="",H18<BW18),K18/24,IF(AND(WEEKDAY(B18)=1,H18>BW18),"24:00"-H18,IF(AND(WEEKDAY(B18)=7,BX19="",BW18<H18),BW18,0)))*24)),"") | R18: =IFERROR(IF(AND(BX18="",BX19=""),"",IF(AND(BX18="x",BX19="x"),K18,IF(BX18="x",IF(H18>BW18,"24:00"-H18,BW18-H18)*24,IF(AND(BX19="x",H18>I18),BW18*24,"")))),"") | X18: =IFERROR(IF(OR(F18="Urlaub",F18="Krank",F18="AZK"),8,IF(OR(F18="Urlaub 50%",F18="AZK 50%"),4,IF(AND(F18="",BX18="x"),8,K18))),"") -> 8 | BV18: =IF(L18="","",(L18/2-1)*2) | BW18: =IFERROR(I18-(J18/24),"") -> 0.16666667 | BX18: =IF(ISERROR(VLOOKUP(B18,CB9:CB177,1,FALSE)),"","x") | BZ18: Tag der Deutschen Einheit | CB18: 43741 | CE18: November | CF18: 2030
A19: =TEXT(B19,"TTT") -> #VALUE! | B19: =B18+1 -> #VALUE! | C19: =IF(H19="","",IF(OR(H19>=0.708333333333333,H19<0.125),"N","")) -> N | E19: Wiesau | F19: Abfarth | H19: 0.83333333 | I19: 0.1875 | J19: =IF(ISBLANK(H19),"",IF(MOD(I19-H19,1)*24<9,0.5,IF(MOD(I19-H19,1)*24>12.5,1,0.75))) -> 0.5 | K19: =IF(F19="Ausfall",6,IF(ISBLANK(H19),"",MOD(I19-H19,1)*24-J19)) -> 8 | L19: 510 | O19: =IFERROR(+MIN(IF(OR(H19="",I19=""),"",(MAX(,MIN(I19-(J19/24)+(H19>I19-(J19/24)),MAX(($CA$4>$CC$4),$CC$4))-MAX(H19,$CA$4))+MAX(,MIN(I19-(J19/24),MAX(($CA$4>$CC$4),$CC$4))-MAX(,$CA$4))*(H19>I19-(J19/24))+MAX(,MIN(I19-(J19/24)+(H19>I19-(J19/24)),MIN(($CA$4>$CC$4),$CC$4))-MAX(H19,))+MIN(I19-(J19/24),MIN(($CA$4>$CC$4),$CC$4))*(H19>I19-(J19/24)))*24),8),"") -> 8 | P19: =IFERROR(IF(H19<0.0451388888888889,IF(AND(WEEKDAY(B20)>0,WEEKDAY(B20)<6),0,IF(AND(WEEKDAY(B20)=7,H19<BW19),K19/24,IF(AND(WEEKDAY(B20)=7,H19>BW19),"24:00"-H19,IF(AND(WEEKDAY(B20)=6,BW19>H19),0,BW19)))*24),IF(AND(WEEKDAY(B19)>0,WEEKDAY(B19)<6),0,IF(AND(WEEKDAY(B19)=7,BX19="",H19<BW19),K19/24,IF(AND(WEEKDAY(B19)=7,H19>BW19),"24:00"-H19,IF(AND(WEEKDAY(B19)=6,BX20="",BW19<H19),BW19,0)))*24)),"") | Q19: =IFERROR(IF(H19<0.0451388888888889,IF(AND(WEEKDAY(B20)>1,WEEKDAY(B20)<7),0,IF(AND(WEEKDAY(B20)=1,H19<BW19),K19/24,IF(AND(WEEKDAY(B20)=1,H19>BW19),"24:00"-H19,IF(AND(WEEKDAY(B20)=7,BW19>H19),0,BW19)))*24),IF(AND(WEEKDAY(B19)>1,WEEKDAY(B19)<7),0,IF(AND(WEEKDAY(B19)=1,BX19="",H19<BW19),K19/24,IF(AND(WEEKDAY(B19)=1,H19>BW19),"24:00"-H19,IF(AND(WEEKDAY(B19)=7,BX20="",BW19<H19),BW19,0)))*24)),"") | R19: =IFERROR(IF(AND(BX19="",BX20=""),"",IF(AND(BX19="x",BX20="x"),K19,IF(BX19="x",IF(H19>BW19,"24:00"-H19,BW19-H19)*24,IF(AND(BX20="x",H19>I19),BW19*24,"")))),"") | X19: =IFERROR(IF(OR(F19="Urlaub",F19="Krank",F19="AZK"),8,IF(OR(F19="Urlaub 50%",F19="AZK 50%"),4,IF(AND(F19="",BX19="x"),8,K19))),"") -> 8 | BV19: =IF(L19="","",(L19/2-1)*2) -> 508 | BW19: =IFERROR(I19-(J19/24),"") -> 0.16666667 | BX19: =IF(ISERROR(VLOOKUP(B19,CB9:CB177,1,FALSE)),"","x") | BZ19: Allerheiligen | CB19: 43770 | CE19: Dezember | CF19: 2031
A20: =TEXT(B20,"TTT") -> #VALUE! | B20: =B19+1 -> #VALUE! | C20: =IF(H20="","",IF(OR(H20>=0.708333333333333,H20<0.125),"N","")) | J20: =IF(ISBLANK(H20),"",IF(MOD(I20-H20,1)*24<9,0.5,IF(MOD(I20-H20,1)*24>12.5,1,0.75))) | K20: =IF(F20="Ausfall",6,IF(ISBLANK(H20),"",MOD(I20-H20,1)*24-J20)) | O20: =IFERROR(+MIN(IF(OR(H20="",I20=""),"",(MAX(,MIN(I20-(J20/24)+(H20>I20-(J20/24)),MAX(($CA$4>$CC$4),$CC$4))-MAX(H20,$CA$4))+MAX(,MIN(I20-(J20/24),MAX(($CA$4>$CC$4),$CC$4))-MAX(,$CA$4))*(H20>I20-(J20/24))+MAX(,MIN(I20-(J20/24)+(H20>I20-(J20/24)),MIN(($CA$4>$CC$4),$CC$4))-MAX(H20,))+MIN(I20-(J20/24),MIN(($CA$4>$CC$4),$CC$4))*(H20>I20-(J20/24)))*24),8),"") | P20: =IFERROR(IF(H20<0.0451388888888889,IF(AND(WEEKDAY(B21)>0,WEEKDAY(B21)<6),0,IF(AND(WEEKDAY(B21)=7,H20<BW20),K20/24,IF(AND(WEEKDAY(B21)=7,H20>BW20),"24:00"-H20,IF(AND(WEEKDAY(B21)=6,BW20>H20),0,BW20)))*24),IF(AND(WEEKDAY(B20)>0,WEEKDAY(B20)<6),0,IF(AND(WEEKDAY(B20)=7,BX20="",H20<BW20),K20/24,IF(AND(WEEKDAY(B20)=7,H20>BW20),"24:00"-H20,IF(AND(WEEKDAY(B20)=6,BX21="",BW20<H20),BW20,0)))*24)),"") | Q20: =IFERROR(IF(H20<0.0451388888888889,IF(AND(WEEKDAY(B21)>1,WEEKDAY(B21)<7),0,IF(AND(WEEKDAY(B21)=1,H20<BW20),K20/24,IF(AND(WEEKDAY(B21)=1,H20>BW20),"24:00"-H20,IF(AND(WEEKDAY(B21)=7,BW20>H20),0,BW20)))*24),IF(AND(WEEKDAY(B20)>1,WEEKDAY(B20)<7),0,IF(AND(WEEKDAY(B20)=1,BX20="",H20<BW20),K20/24,IF(AND(WEEKDAY(B20)=1,H20>BW20),"24:00"-H20,IF(AND(WEEKDAY(B20)=7,BX21="",BW20<H20),BW20,0)))*24)),"") | R20: =IFERROR(IF(AND(BX20="",BX21=""),"",IF(AND(BX20="x",BX21="x"),K20,IF(BX20="x",IF(H20>BW20,"24:00"-H20,BW20-H20)*24,IF(AND(BX21="x",H20>I20),BW20*24,"")))),"") | X20: =IFERROR(IF(OR(F20="Urlaub",F20="Krank",F20="AZK"),8,IF(OR(F20="Urlaub 50%",F20="AZK 50%"),4,IF(AND(F20="",BX20="x"),8,K20))),"") | BV20: =IF(L20="","",(L20/2-1)*2) | BW20: =IFERROR(I20-(J20/24),"") | BX20: =IF(ISERROR(VLOOKUP(B20,CB9:CB177,1,FALSE)),"","x") | BZ20: 1. Weihnachtsfeiertag | CB20: 43824
A21: =TEXT(B21,"TTT") -> #VALUE! | B21: =B20+1 -> #VALUE! | C21: =IF(H21="","",IF(OR(H21>=0.708333333333333,H21<0.125),"N","")) -> N | E21: Kassel | F21: An-Abfarth | G21: Fahrer | H21: 0.83333333 | I21: 0.1875 | J21: =IF(ISBLANK(H21),"",IF(MOD(I21-H21,1)*24<9,0.5,IF(MOD(I21-H21,1)*24>12.5,1,0.75))) -> 0.5 | K21: =IF(F21="Ausfall",6,IF(ISBLANK(H21),"",MOD(I21-H21,1)*24-J21)) -> 8 | L21: 280 | O21: =IFERROR(+MIN(IF(OR(H21="",I21=""),"",(MAX(,MIN(I21-(J21/24)+(H21>I21-(J21/24)),MAX(($CA$4>$CC$4),$CC$4))-MAX(H21,$CA$4))+MAX(,MIN(I21-(J21/24),MAX(($CA$4>$CC$4),$CC$4))-MAX(,$CA$4))*(H21>I21-(J21/24))+MAX(,MIN(I21-(J21/24)+(H21>I21-(J21/24)),MIN(($CA$4>$CC$4),$CC$4))-MAX(H21,))+MIN(I21-(J21/24),MIN(($CA$4>$CC$4),$CC$4))*(H21>I21-(J21/24)))*24),8),"") -> 8 | P21: =IFERROR(IF(H21<0.0451388888888889,IF(AND(WEEKDAY(B22)>0,WEEKDAY(B22)<6),0,IF(AND(WEEKDAY(B22)=7,H21<BW21),K21/24,IF(AND(WEEKDAY(B22)=7,H21>BW21),"24:00"-H21,IF(AND(WEEKDAY(B22)=6,BW21>H21),0,BW21)))*24),IF(AND(WEEKDAY(B21)>0,WEEKDAY(B21)<6),0,IF(AND(WEEKDAY(B21)=7,BX21="",H21<BW21),K21/24,IF(AND(WEEKDAY(B21)=7,H21>BW21),"24:00"-H21,IF(AND(WEEKDAY(B21)=6,BX22="",BW21<H21),BW21,0)))*24)),"") | Q21: =IFERROR(IF(H21<0.0451388888888889,IF(AND(WEEKDAY(B22)>1,WEEKDAY(B22)<7),0,IF(AND(WEEKDAY(B22)=1,H21<BW21),K21/24,IF(AND(WEEKDAY(B22)=1,H21>BW21),"24:00"-H21,IF(AND(WEEKDAY(B22)=7,BW21>H21),0,BW21)))*24),IF(AND(WEEKDAY(B21)>1,WEEKDAY(B21)<7),0,IF(AND(WEEKDAY(B21)=1,BX21="",H21<BW21),K21/24,IF(AND(WEEKDAY(B21)=1,H21>BW21),"24:00"-H21,IF(AND(WEEKDAY(B21)=7,BX22="",BW21<H21),BW21,0)))*24)),"") | R21: =IFERROR(IF(AND(BX21="",BX22=""),"",IF(AND(BX21="x",BX22="x"),K21,IF(BX21="x",IF(H21>BW21,"24:00"-H21,BW21-H21)*24,IF(AND(BX22="x",H21>I21),BW21*24,"")))),"") | X21: =IFERROR(IF(OR(F21="Urlaub",F21="Krank",F21="AZK"),8,IF(OR(F21="Urlaub 50%",F21="AZK 50%"),4,IF(AND(F21="",BX21="x"),8,K21))),"") -> 8 | BV21: =IF(L21="","",(L21/2-1)*2) -> 278 | BW21: =IFERROR(I21-(J21/24),"") -> 0.16666667 | BX21: =IF(ISERROR(VLOOKUP(B21,CB9:CB177,1,FALSE)),"","x") | BZ21: 2. Weihnachtsfeiertag | CB21: 43825
A22: =TEXT(B22,"TTT") -> #VALUE! | B22: =B21+1 -> #VALUE! | C22: =IF(H22="","",IF(OR(H22>=0.708333333333333,H22<0.125),"N","")) -> N | E22: Kassel | F22: Anfarth | H22: 0.91666667 | I22: 0.1875 | J22: =IF(ISBLANK(H22),"",IF(MOD(I22-H22,1)*24<9,0.5,IF(MOD(I22-H22,1)*24>12.5,1,0.75))) -> 0.5 | K22: =IF(F22="Ausfall",6,IF(ISBLANK(H22),"",MOD(I22-H22,1)*24-J22)) -> 6 | L22: 140 | O22: =IFERROR(+MIN(IF(OR(H22="",I22=""),"",(MAX(,MIN(I22-(J22/24)+(H22>I22-(J22/24)),MAX(($CA$4>$CC$4),$CC$4))-MAX(H22,$CA$4))+MAX(,MIN(I22-(J22/24),MAX(($CA$4>$CC$4),$CC$4))-MAX(,$CA$4))*(H22>I22-(J22/24))+MAX(,MIN(I22-(J22/24)+(H22>I22-(J22/24)),MIN(($CA$4>$CC$4),$CC$4))-MAX(H22,))+MIN(I22-(J22/24),MIN(($CA$4>$CC$4),$CC$4))*(H22>I22-(J22/24)))*24),8),"") -> 6 | P22: =IFERROR(IF(H22<0.0451388888888889,IF(AND(WEEKDAY(B23)>0,WEEKDAY(B23)<6),0,IF(AND(WEEKDAY(B23)=7,H22<BW22),K22/24,IF(AND(WEEKDAY(B23)=7,H22>BW22),"24:00"-H22,IF(AND(WEEKDAY(B23)=6,BW22>H22),0,BW22)))*24),IF(AND(WEEKDAY(B22)>0,WEEKDAY(B22)<6),0,IF(AND(WEEKDAY(B22)=7,BX22="",H22<BW22),K22/24,IF(AND(WEEKDAY(B22)=7,H22>BW22),"24:00"-H22,IF(AND(WEEKDAY(B22)=6,BX23="",BW22<H22),BW22,0)))*24)),"") | Q22: =IFERROR(IF(H22<0.0451388888888889,IF(AND(WEEKDAY(B23)>1,WEEKDAY(B23)<7),0,IF(AND(WEEKDAY(B23)=1,H22<BW22),K22/24,IF(AND(WEEKDAY(B23)=1,H22>BW22),"24:00"-H22,IF(AND(WEEKDAY(B23)=7,BW22>H22),0,BW22)))*24),IF(AND(WEEKDAY(B22)>1,WEEKDAY(B22)<7),0,IF(AND(WEEKDAY(B22)=1,BX22="",H22<BW22),K22/24,IF(AND(WEEKDAY(B22)=1,H22>BW22),"24:00"-H22,IF(AND(WEEKDAY(B22)=7,BX23="",BW22<H22),BW22,0)))*24)),"") | R22: =IFERROR(IF(AND(BX22="",BX23=""),"",IF(AND(BX22="x",BX23="x"),K22,IF(BX22="x",IF(H22>BW22,"24:00"-H22,BW22-H22)*24,IF(AND(BX23="x",H22>I22),BW22*24,"")))),"") | X22: =IFERROR(IF(OR(F22="Urlaub",F22="Krank",F22="AZK"),8,IF(OR(F22="Urlaub 50%",F22="AZK 50%"),4,IF(AND(F22="",BX22="x"),8,K22))),"") -> 6 | BV22: =IF(L22="","",(L22/2-1)*2) -> 138 | BW22: =IFERROR(I22-(J22/24),"") -> 0.16666667 | BX22: =IF(ISERROR(VLOOKUP(B22,CB9:CB177,1,FALSE)),"","x")
A23: =TEXT(B23,"TTT") -> #VALUE! | B23: =B22+1 -> #VALUE! | C23: =IF(H23="","",IF(OR(H23>=0.708333333333333,H23<0.125),"N","")) -> N | E23: Kassel | H23: 0.875 | I23: 0.32291667 | J23: =IF(ISBLANK(H23),"",IF(MOD(I23-H23,1)*24<9,0.5,IF(MOD(I23-H23,1)*24>12.5,1,0.75))) -> 0.75 | K23: =IF(F23="Ausfall",6,IF(ISBLANK(H23),"",MOD(I23-H23,1)*24-J23)) -> 10 | O23: =IFERROR(+MIN(IF(OR(H23="",I23=""),"",(MAX(,MIN(I23-(J23/24)+(H23>I23-(J23/24)),MAX(($CA$4>$CC$4),$CC$4))-MAX(H23,$CA$4))+MAX(,MIN(I23-(J23/24),MAX(($CA$4>$CC$4),$CC$4))-MAX(,$CA$4))*(H23>I23-(J23/24))+MAX(,MIN(I23-(J23/24)+(H23>I23-(J23/24)),MIN(($CA$4>$CC$4),$CC$4))-MAX(H23,))+MIN(I23-(J23/24),MIN(($CA$4>$CC$4),$CC$4))*(H23>I23-(J23/24)))*24),8),"") -> 8 | P23: =IFERROR(IF(H23<0.0451388888888889,IF(AND(WEEKDAY(B24)>0,WEEKDAY(B24)<6),0,IF(AND(WEEKDAY(B24)=7,H23<BW23),K23/24,IF(AND(WEEKDAY(B24)=7,H23>BW23),"24:00"-H23,IF(AND(WEEKDAY(B24)=6,BW23>H23),0,BW23)))*24),IF(AND(WEEKDAY(B23)>0,WEEKDAY(B23)<6),0,IF(AND(WEEKDAY(B23)=7,BX23="",H23<BW23),K23/24,IF(AND(WEEKDAY(B23)=7,H23>BW23),"24:00"-H23,IF(AND(WEEKDAY(B23)=6,BX24="",BW23<H23),BW23,0)))*24)),"") | Q23: =IFERROR(IF(H23<0.0451388888888889,IF(AND(WEEKDAY(B24)>1,WEEKDAY(B24)<7),0,IF(AND(WEEKDAY(B24)=1,H23<BW23),K23/24,IF(AND(WEEKDAY(B24)=1,H23>BW23),"24:00"-H23,IF(AND(WEEKDAY(B24)=7,BW23>H23),0,BW23)))*24),IF(AND(WEEKDAY(B23)>1,WEEKDAY(B23)<7),0,IF(AND(WEEKDAY(B23)=1,BX23="",H23<BW23),K23/24,IF(AND(WEEKDAY(B23)=1,H23>BW23),"24:00"-H23,IF(AND(WEEKDAY(B23)=7,BX24="",BW23<H23),BW23,0)))*24)),"") | R23: =IFERROR(IF(AND(BX23="",BX24=""),"",IF(AND(BX23="x",BX24="x"),K23,IF(BX23="x",IF(H23>BW23,"24:00"-H23,BW23-H23)*24,IF(AND(BX24="x",H23>I23),BW23*24,"")))),"") | X23: =IFERROR(IF(OR(F23="Urlaub",F23="Krank",F23="AZK"),8,IF(OR(F23="Urlaub 50%",F23="AZK 50%"),4,IF(AND(F23="",BX23="x"),8,K23))),"") -> 10 | BV23: =IF(L23="","",(L23/2-1)*2) | BW23: =IFERROR(I23-(J23/24),"") -> 0.29166667 | BX23: =IF(ISERROR(VLOOKUP(B23,CB9:CB177,1,FALSE)),"","x") | BZ23: Neujahr | CB23: 43831
A24: =TEXT(B24,"TTT") -> #VALUE! | B24: =B23+1 -> #VALUE! | C24: =IF(H24="","",IF(OR(H24>=0.708333333333333,H24<0.125),"N","")) -> N | E24: Kassel | H24: 0.91666667 | I24: 0.27083333 | J24: =IF(ISBLANK(H24),"",IF(MOD(I24-H24,1)*24<9,0.5,IF(MOD(I24-H24,1)*24>12.5,1,0.75))) -> 0.5 | K24: =IF(F24="Ausfall",6,IF(ISBLANK(H24),"",MOD(I24-H24,1)*24-J24)) -> 8 | O24: =IFERROR(+MIN(IF(OR(H24="",I24=""),"",(MAX(,MIN(I24-(J24/24)+(H24>I24-(J24/24)),MAX(($CA$4>$CC$4),$CC$4))-MAX(H24,$CA$4))+MAX(,MIN(I24-(J24/24),MAX(($CA$4>$CC$4),$CC$4))-MAX(,$CA$4))*(H24>I24-(J24/24))+MAX(,MIN(I24-(J24/24)+(H24>I24-(J24/24)),MIN(($CA$4>$CC$4),$CC$4))-MAX(H24,))+MIN(I24-(J24/24),MIN(($CA$4>$CC$4),$CC$4))*(H24>I24-(J24/24)))*24),8),"") -> 8 | P24: =IFERROR(IF(H24<0.0451388888888889,IF(AND(WEEKDAY(B25)>0,WEEKDAY(B25)<6),0,IF(AND(WEEKDAY(B25)=7,H24<BW24),K24/24,IF(AND(WEEKDAY(B25)=7,H24>BW24),"24:00"-H24,IF(AND(WEEKDAY(B25)=6,BW24>H24),0,BW24)))*24),IF(AND(WEEKDAY(B24)>0,WEEKDAY(B24)<6),0,IF(AND(WEEKDAY(B24)=7,BX24="",H24<BW24),K24/24,IF(AND(WEEKDAY(B24)=7,H24>BW24),"24:00"-H24,IF(AND(WEEKDAY(B24)=6,BX25="",BW24<H24),BW24,0)))*24)),"") | Q24: =IFERROR(IF(H24<0.0451388888888889,IF(AND(WEEKDAY(B25)>1,WEEKDAY(B25)<7),0,IF(AND(WEEKDAY(B25)=1,H24<BW24),K24/24,IF(AND(WEEKDAY(B25)=1,H24>BW24),"24:00"-H24,IF(AND(WEEKDAY(B25)=7,BW24>H24),0,BW24)))*24),IF(AND(WEEKDAY(B24)>1,WEEKDAY(B24)<7),0,IF(AND(WEEKDAY(B24)=1,BX24="",H24<BW24),K24/24,IF(AND(WEEKDAY(B24)=1,H24>BW24),"24:00"-H24,IF(AND(WEEKDAY(B24)=7,BX25="",BW24<H24),BW24,0)))*24)),"") | R24: =IFERROR(IF(AND(BX24="",BX25=""),"",IF(AND(BX24="x",BX25="x"),K24,IF(BX24="x",IF(H24>BW24,"24:00"-H24,BW24-H24)*24,IF(AND(BX25="x",H24>I24),BW24*24,"")))),"") | X24: =IFERROR(IF(OR(F24="Urlaub",F24="Krank",F24="AZK"),8,IF(OR(F24="Urlaub 50%",F24="AZK 50%"),4,IF(AND(F24="",BX24="x"),8,K24))),"") -> 8 | BV24: =IF(L24="","",(L24/2-1)*2) | BW24: =IFERROR(I24-(J24/24),"") -> 0.25 | BX24: =IF(ISERROR(VLOOKUP(B24,CB9:CB177,1,FALSE)),"","x") | BZ24: Karfreitag | CB24: 43931
A25: =TEXT(B25,"TTT") -> #VALUE! | B25: =B24+1 -> #VALUE! | C25: =IF(H25="","",IF(OR(H25>=0.708333333333333,H25<0.125),"N","")) | E25: Kassel | F25: Abfarth | J25: =IF(ISBLANK(H25),"",IF(MOD(I25-H25,1)*24<9,0.5,IF(MOD(I25-H25,1)*24>12.5,1,0.75))) | K25: =IF(F25="Ausfall",6,IF(ISBLANK(H25),"",MOD(I25-H25,1)*24-J25)) | L25: 140 | O25: =IFERROR(+MIN(IF(OR(H25="",I25=""),"",(MAX(,MIN(I25-(J25/24)+(H25>I25-(J25/24)),MAX(($CA$4>$CC$4),$CC$4))-MAX(H25,$CA$4))+MAX(,MIN(I25-(J25/24),MAX(($CA$4>$CC$4),$CC$4))-MAX(,$CA$4))*(H25>I25-(J25/24))+MAX(,MIN(I25-(J25/24)+(H25>I25-(J25/24)),MIN(($CA$4>$CC$4),$CC$4))-MAX(H25,))+MIN(I25-(J25/24),MIN(($CA$4>$CC$4),$CC$4))*(H25>I25-(J25/24)))*24),8),"") | P25: =IFERROR(IF(H25<0.0451388888888889,IF(AND(WEEKDAY(B26)>0,WEEKDAY(B26)<6),0,IF(AND(WEEKDAY(B26)=7,H25<BW25),K25/24,IF(AND(WEEKDAY(B26)=7,H25>BW25),"24:00"-H25,IF(AND(WEEKDAY(B26)=6,BW25>H25),0,BW25)))*24),IF(AND(WEEKDAY(B25)>0,WEEKDAY(B25)<6),0,IF(AND(WEEKDAY(B25)=7,BX25="",H25<BW25),K25/24,IF(AND(WEEKDAY(B25)=7,H25>BW25),"24:00"-H25,IF(AND(WEEKDAY(B25)=6,BX26="",BW25<H25),BW25,0)))*24)),"") | Q25: =IFERROR(IF(H25<0.0451388888888889,IF(AND(WEEKDAY(B26)>1,WEEKDAY(B26)<7),0,IF(AND(WEEKDAY(B26)=1,H25<BW25),K25/24,IF(AND(WEEKDAY(B26)=1,H25>BW25),"24:00"-H25,IF(AND(WEEKDAY(B26)=7,BW25>H25),0,BW25)))*24),IF(AND(WEEKDAY(B25)>1,WEEKDAY(B25)<7),0,IF(AND(WEEKDAY(B25)=1,BX25="",H25<BW25),K25/24,IF(AND(WEEKDAY(B25)=1,H25>BW25),"24:00"-H25,IF(AND(WEEKDAY(B25)=7,BX26="",BW25<H25),BW25,0)))*24)),"") | R25: =IFERROR(IF(AND(BX25="",BX26=""),"",IF(AND(BX25="x",BX26="x"),K25,IF(BX25="x",IF(H25>BW25,"24:00"-H25,BW25-H25)*24,IF(AND(BX26="x",H25>I25),BW25*24,"")))),"") | X25: =IFERROR(IF(OR(F25="Urlaub",F25="Krank",F25="AZK"),8,IF(OR(F25="Urlaub 50%",F25="AZK 50%"),4,IF(AND(F25="",BX25="x"),8,K25))),"") | BV25: =IF(L25="","",(L25/2-1)*2) -> 138 | BW25: =IFERROR(I25-(J25/24),"") | BX25: =IF(ISERROR(VLOOKUP(B25,CB9:CB177,1,FALSE)),"","x") | BZ25: Ostersonntag | CB25: 43933
A26: =TEXT(B26,"TTT") -> #VALUE! | B26: =B25+1 -> #VALUE! | C26: =IF(H26="","",IF(OR(H26>=0.708333333333333,H26<0.125),"N","")) -> N | E26: Luxemburg | F26: An-Abfarth | H26: 0.83333333 | I26: 0.28125 | J26: =IF(ISBLANK(H26),"",IF(MOD(I26-H26,1)*24<9,0.5,IF(MOD(I26-H26,1)*24>12.5,1,0.75))) -> 0.75 | K26: =IF(F26="Ausfall",6,IF(ISBLANK(H26),"",MOD(I26-H26,1)*24-J26)) -> 10 | L26: 420 | O26: =IFERROR(+MIN(IF(OR(H26="",I26=""),"",(MAX(,MIN(I26-(J26/24)+(H26>I26-(J26/24)),MAX(($CA$4>$CC$4),$CC$4))-MAX(H26,$CA$4))+MAX(,MIN(I26-(J26/24),MAX(($CA$4>$CC$4),$CC$4))-MAX(,$CA$4))*(H26>I26-(J26/24))+MAX(,MIN(I26-(J26/24)+(H26>I26-(J26/24)),MIN(($CA$4>$CC$4),$CC$4))-MAX(H26,))+MIN(I26-(J26/24),MIN(($CA$4>$CC$4),$CC$4))*(H26>I26-(J26/24)))*24),8),"") -> 8 | P26: =IFERROR(IF(H26<0.0451388888888889,IF(AND(WEEKDAY(B27)>0,WEEKDAY(B27)<6),0,IF(AND(WEEKDAY(B27)=7,H26<BW26),K26/24,IF(AND(WEEKDAY(B27)=7,H26>BW26),"24:00"-H26,IF(AND(WEEKDAY(B27)=6,BW26>H26),0,BW26)))*24),IF(AND(WEEKDAY(B26)>0,WEEKDAY(B26)<6),0,IF(AND(WEEKDAY(B26)=7,BX26="",H26<BW26),K26/24,IF(AND(WEEKDAY(B26)=7,H26>BW26),"24:00"-H26,IF(AND(WEEKDAY(B26)=6,BX27="",BW26<H26),BW26,0)))*24)),"") | Q26: =IFERROR(IF(H26<0.0451388888888889,IF(AND(WEEKDAY(B27)>1,WEEKDAY(B27)<7),0,IF(AND(WEEKDAY(B27)=1,H26<BW26),K26/24,IF(AND(WEEKDAY(B27)=1,H26>BW26),"24:00"-H26,IF(AND(WEEKDAY(B27)=7,BW26>H26),0,BW26)))*24),IF(AND(WEEKDAY(B26)>1,WEEKDAY(B26)<7),0,IF(AND(WEEKDAY(B26)=1,BX26="",H26<BW26),K26/24,IF(AND(WEEKDAY(B26)=1,H26>BW26),"24:00"-H26,IF(AND(WEEKDAY(B26)=7,BX27="",BW26<H26),BW26,0)))*24)),"") | R26: =IFERROR(IF(AND(BX26="",BX27=""),"",IF(AND(BX26="x",BX27="x"),K26,IF(BX26="x",IF(H26>BW26,"24:00"-H26,BW26-H26)*24,IF(AND(BX27="x",H26>I26),BW26*24,"")))),"") | X26: =IFERROR(IF(OR(F26="Urlaub",F26="Krank",F26="AZK"),8,IF(OR(F26="Urlaub 50%",F26="AZK 50%"),4,IF(AND(F26="",BX26="x"),8,K26))),"") -> 10 | BV26: =IF(L26="","",(L26/2-1)*2) -> 418 | BW26: =IFERROR(I26-(J26/24),"") -> 0.25 | BX26: =IF(ISERROR(VLOOKUP(B26,CB9:CB177,1,FALSE)),"","x") | BZ26: Ostermontag | CB26: 43934
A27: =TEXT(B27,"TTT") -> #VALUE! | B27: =B26+1 -> #VALUE! | C27: =IF(H27="","",IF(OR(H27>=0.708333333333333,H27<0.125),"N","")) | J27: =IF(ISBLANK(H27),"",IF(MOD(I27-H27,1)*24<9,0.5,IF(MOD(I27-H27,1)*24>12.5,1,0.75))) | K27: =IF(F27="Ausfall",6,IF(ISBLANK(H27),"",MOD(I27-H27,1)*24-J27)) | O27: =IFERROR(+MIN(IF(OR(H27="",I27=""),"",(MAX(,MIN(I27-(J27/24)+(H27>I27-(J27/24)),MAX(($CA$4>$CC$4),$CC$4))-MAX(H27,$CA$4))+MAX(,MIN(I27-(J27/24),MAX(($CA$4>$CC$4),$CC$4))-MAX(,$CA$4))*(H27>I27-(J27/24))+MAX(,MIN(I27-(J27/24)+(H27>I27-(J27/24)),MIN(($CA$4>$CC$4),$CC$4))-MAX(H27,))+MIN(I27-(J27/24),MIN(($CA$4>$CC$4),$CC$4))*(H27>I27-(J27/24)))*24),8),"") | P27: =IFERROR(IF(H27<0.0451388888888889,IF(AND(WEEKDAY(B28)>0,WEEKDAY(B28)<6),0,IF(AND(WEEKDAY(B28)=7,H27<BW27),K27/24,IF(AND(WEEKDAY(B28)=7,H27>BW27),"24:00"-H27,IF(AND(WEEKDAY(B28)=6,BW27>H27),0,BW27)))*24),IF(AND(WEEKDAY(B27)>0,WEEKDAY(B27)<6),0,IF(AND(WEEKDAY(B27)=7,BX27="",H27<BW27),K27/24,IF(AND(WEEKDAY(B27)=7,H27>BW27),"24:00"-H27,IF(AND(WEEKDAY(B27)=6,BX28="",BW27<H27),BW27,0)))*24)),"") | Q27: =IFERROR(IF(H27<0.0451388888888889,IF(AND(WEEKDAY(B28)>1,WEEKDAY(B28)<7),0,IF(AND(WEEKDAY(B28)=1,H27<BW27),K27/24,IF(AND(WEEKDAY(B28)=1,H27>BW27),"24:00"-H27,IF(AND(WEEKDAY(B28)=7,BW27>H27),0,BW27)))*24),IF(AND(WEEKDAY(B27)>1,WEEKDAY(B27)<7),0,IF(AND(WEEKDAY(B27)=1,BX27="",H27<BW27),K27/24,IF(AND(WEEKDAY(B27)=1,H27>BW27),"24:00"-H27,IF(AND(WEEKDAY(B27)=7,BX28="",BW27<H27),BW27,0)))*24)),"") | R27: =IFERROR(IF(AND(BX27="",BX28=""),"",IF(AND(BX27="x",BX28="x"),K27,IF(BX27="x",IF(H27>BW27,"24:00"-H27,BW27-H27)*24,IF(AND(BX28="x",H27>I27),BW27*24,"")))),"") | X27: =IFERROR(IF(OR(F27="Urlaub",F27="Krank",F27="AZK"),8,IF(OR(F27="Urlaub 50%",F27="AZK 50%"),4,IF(AND(F27="",BX27="x"),8,K27))),"") | BV27: =IF(L27="","",(L27/2-1)*2) | BW27: =IFERROR(I27-(J27/24),"") | BX27: =IF(ISERROR(VLOOKUP(B27,CB9:CB177,1,FALSE)),"","x") | BZ27: Tag der Arbeit | CB27: 43952
A28: =TEXT(B28,"TTT") -> #VALUE! | B28: =B27+1 -> #VALUE! | C28: =IF(H28="","",IF(OR(H28>=0.708333333333333,H28<0.125),"N","")) | J28: =IF(ISBLANK(H28),"",IF(MOD(I28-H28,1)*24<9,0.5,IF(MOD(I28-H28,1)*24>12.5,1,0.75))) | K28: =IF(F28="Ausfall",6,IF(ISBLANK(H28),"",MOD(I28-H28,1)*24-J28)) | O28: =IFERROR(+MIN(IF(OR(H28="",I28=""),"",(MAX(,MIN(I28-(J28/24)+(H28>I28-(J28/24)),MAX(($CA$4>$CC$4),$CC$4))-MAX(H28,$CA$4))+MAX(,MIN(I28-(J28/24),MAX(($CA$4>$CC$4),$CC$4))-MAX(,$CA$4))*(H28>I28-(J28/24))+MAX(,MIN(I28-(J28/24)+(H28>I28-(J28/24)),MIN(($CA$4>$CC$4),$CC$4))-MAX(H28,))+MIN(I28-(J28/24),MIN(($CA$4>$CC$4),$CC$4))*(H28>I28-(J28/24)))*24),8),"") | P28: =IFERROR(IF(H28<0.0451388888888889,IF(AND(WEEKDAY(B29)>0,WEEKDAY(B29)<6),0,IF(AND(WEEKDAY(B29)=7,H28<BW28),K28/24,IF(AND(WEEKDAY(B29)=7,H28>BW28),"24:00"-H28,IF(AND(WEEKDAY(B29)=6,BW28>H28),0,BW28)))*24),IF(AND(WEEKDAY(B28)>0,WEEKDAY(B28)<6),0,IF(AND(WEEKDAY(B28)=7,BX28="",H28<BW28),K28/24,IF(AND(WEEKDAY(B28)=7,H28>BW28),"24:00"-H28,IF(AND(WEEKDAY(B28)=6,BX29="",BW28<H28),BW28,0)))*24)),"") | Q28: =IFERROR(IF(H28<0.0451388888888889,IF(AND(WEEKDAY(B29)>1,WEEKDAY(B29)<7),0,IF(AND(WEEKDAY(B29)=1,H28<BW28),K28/24,IF(AND(WEEKDAY(B29)=1,H28>BW28),"24:00"-H28,IF(AND(WEEKDAY(B29)=7,BW28>H28),0,BW28)))*24),IF(AND(WEEKDAY(B28)>1,WEEKDAY(B28)<7),0,IF(AND(WEEKDAY(B28)=1,BX28="",H28<BW28),K28/24,IF(AND(WEEKDAY(B28)=1,H28>BW28),"24:00"-H28,IF(AND(WEEKDAY(B28)=7,BX29="",BW28<H28),BW28,0)))*24)),"") | R28: =IFERROR(IF(AND(BX28="",BX29=""),"",IF(AND(BX28="x",BX29="x"),K28,IF(BX28="x",IF(H28>BW28,"24:00"-H28,BW28-H28)*24,IF(AND(BX29="x",H28>I28),BW28*24,"")))),"") | X28: =IFERROR(IF(OR(F28="Urlaub",F28="Krank",F28="AZK"),8,IF(OR(F28="Urlaub 50%",F28="AZK 50%"),4,IF(AND(F28="",BX28="x"),8,K28))),"") | BV28: =IF(L28="","",(L28/2-1)*2) | BW28: =IFERROR(I28-(J28/24),"") | BX28: =IF(ISERROR(VLOOKUP(B28,CB9:CB177,1,FALSE)),"","x") | BZ28: Christi Himmelfahrt | CB28: 43972
A29: =TEXT(B29,"TTT") -> #VALUE! | B29: =B28+1 -> #VALUE! | C29: =IF(H29="","",IF(OR(H29>=0.708333333333333,H29<0.125),"N","")) | J29: =IF(ISBLANK(H29),"",IF(MOD(I29-H29,1)*24<9,0.5,IF(MOD(I29-H29,1)*24>12.5,1,0.75))) | K29: =IF(F29="Ausfall",6,IF(ISBLANK(H29),"",MOD(I29-H29,1)*24-J29)) | O29: =IFERROR(+MIN(IF(OR(H29="",I29=""),"",(MAX(,MIN(I29-(J29/24)+(H29>I29-(J29/24)),MAX(($CA$4>$CC$4),$CC$4))-MAX(H29,$CA$4))+MAX(,MIN(I29-(J29/24),MAX(($CA$4>$CC$4),$CC$4))-MAX(,$CA$4))*(H29>I29-(J29/24))+MAX(,MIN(I29-(J29/24)+(H29>I29-(J29/24)),MIN(($CA$4>$CC$4),$CC$4))-MAX(H29,))+MIN(I29-(J29/24),MIN(($CA$4>$CC$4),$CC$4))*(H29>I29-(J29/24)))*24),8),"") | P29: =IFERROR(IF(H29<0.0451388888888889,IF(AND(WEEKDAY(B30)>0,WEEKDAY(B30)<6),0,IF(AND(WEEKDAY(B30)=7,H29<BW29),K29/24,IF(AND(WEEKDAY(B30)=7,H29>BW29),"24:00"-H29,IF(AND(WEEKDAY(B30)=6,BW29>H29),0,BW29)))*24),IF(AND(WEEKDAY(B29)>0,WEEKDAY(B29)<6),0,IF(AND(WEEKDAY(B29)=7,BX29="",H29<BW29),K29/24,IF(AND(WEEKDAY(B29)=7,H29>BW29),"24:00"-H29,IF(AND(WEEKDAY(B29)=6,BX30="",BW29<H29),BW29,0)))*24)),"") | Q29: =IFERROR(IF(H29<0.0451388888888889,IF(AND(WEEKDAY(B30)>1,WEEKDAY(B30)<7),0,IF(AND(WEEKDAY(B30)=1,H29<BW29),K29/24,IF(AND(WEEKDAY(B30)=1,H29>BW29),"24:00"-H29,IF(AND(WEEKDAY(B30)=7,BW29>H29),0,BW29)))*24),IF(AND(WEEKDAY(B29)>1,WEEKDAY(B29)<7),0,IF(AND(WEEKDAY(B29)=1,BX29="",H29<BW29),K29/24,IF(AND(WEEKDAY(B29)=1,H29>BW29),"24:00"-H29,IF(AND(WEEKDAY(B29)=7,BX30="",BW29<H29),BW29,0)))*24)),"") | R29: =IFERROR(IF(AND(BX29="",BX30=""),"",IF(AND(BX29="x",BX30="x"),K29,IF(BX29="x",IF(H29>BW29,"24:00"-H29,BW29-H29)*24,IF(AND(BX30="x",H29>I29),BW29*24,"")))),"") | X29: =IFERROR(IF(OR(F29="Urlaub",F29="Krank",F29="AZK"),8,IF(OR(F29="Urlaub 50%",F29="AZK 50%"),4,IF(AND(F29="",BX29="x"),8,K29))),"") | BV29: =IF(L29="","",(L29/2-1)*2) | BW29: =IFERROR(I29-(J29/24),"") | BX29: =IF(ISERROR(VLOOKUP(B29,CB9:CB177,1,FALSE)),"","x") | BZ29: Pfingstsonntag | CB29: 43981
A30: =TEXT(B30,"TTT") -> #VALUE! | B30: =B29+1 -> #VALUE! | C30: =IF(H30="","",IF(OR(H30>=0.708333333333333,H30<0.125),"N","")) | J30: =IF(ISBLANK(H30),"",IF(MOD(I30-H30,1)*24<9,0.5,IF(MOD(I30-H30,1)*24>12.5,1,0.75))) | K30: =IF(F30="Ausfall",6,IF(ISBLANK(H30),"",MOD(I30-H30,1)*24-J30)) | O30: =IFERROR(+MIN(IF(OR(H30="",I30=""),"",(MAX(,MIN(I30-(J30/24)+(H30>I30-(J30/24)),MAX(($CA$4>$CC$4),$CC$4))-MAX(H30,$CA$4))+MAX(,MIN(I30-(J30/24),MAX(($CA$4>$CC$4),$CC$4))-MAX(,$CA$4))*(H30>I30-(J30/24))+MAX(,MIN(I30-(J30/24)+(H30>I30-(J30/24)),MIN(($CA$4>$CC$4),$CC$4))-MAX(H30,))+MIN(I30-(J30/24),MIN(($CA$4>$CC$4),$CC$4))*(H30>I30-(J30/24)))*24),8),"") | P30: =IFERROR(IF(H30<0.0451388888888889,IF(AND(WEEKDAY(B31)>0,WEEKDAY(B31)<6),0,IF(AND(WEEKDAY(B31)=7,H30<BW30),K30/24,IF(AND(WEEKDAY(B31)=7,H30>BW30),"24:00"-H30,IF(AND(WEEKDAY(B31)=6,BW30>H30),0,BW30)))*24),IF(AND(WEEKDAY(B30)>0,WEEKDAY(B30)<6),0,IF(AND(WEEKDAY(B30)=7,BX30="",H30<BW30),K30/24,IF(AND(WEEKDAY(B30)=7,H30>BW30),"24:00"-H30,IF(AND(WEEKDAY(B30)=6,BX31="",BW30<H30),BW30,0)))*24)),"") | Q30: =IFERROR(IF(H30<0.0451388888888889,IF(AND(WEEKDAY(B31)>1,WEEKDAY(B31)<7),0,IF(AND(WEEKDAY(B31)=1,H30<BW30),K30/24,IF(AND(WEEKDAY(B31)=1,H30>BW30),"24:00"-H30,IF(AND(WEEKDAY(B31)=7,BW30>H30),0,BW30)))*24),IF(AND(WEEKDAY(B30)>1,WEEKDAY(B30)<7),0,IF(AND(WEEKDAY(B30)=1,BX30="",H30<BW30),K30/24,IF(AND(WEEKDAY(B30)=1,H30>BW30),"24:00"-H30,IF(AND(WEEKDAY(B30)=7,BX31="",BW30<H30),BW30,0)))*24)),"") | R30: =IFERROR(IF(AND(BX30="",BX31=""),"",IF(AND(BX30="x",BX31="x"),K30,IF(BX30="x",IF(H30>BW30,"24:00"-H30,BW30-H30)*24,IF(AND(BX31="x",H30>I30),BW30*24,"")))),"") | X30: =IFERROR(IF(OR(F30="Urlaub",F30="Krank",F30="AZK"),8,IF(OR(F30="Urlaub 50%",F30="AZK 50%"),4,IF(AND(F30="",BX30="x"),8,K30))),"") | BV30: =IF(L30="","",(L30/2-1)*2) | BW30: =IFERROR(I30-(J30/24),"") | BX30: =IF(ISERROR(VLOOKUP(B30,CB9:CB177,1,FALSE)),"","x") | BZ30: Pfingstmontag | CB30: 43983
A31: =TEXT(B31,"TTT") -> #VALUE! | B31: =B30+1 -> #VALUE! | C31: =IF(H31="","",IF(OR(H31>=0.708333333333333,H31<0.125),"N","")) -> N | E31: Hannover | F31: An-Abfarth | G31: Fahrer Privat Auto | H31: 0.83333333 | I31: 0.1875 | J31: =IF(ISBLANK(H31),"",IF(MOD(I31-H31,1)*24<9,0.5,IF(MOD(I31-H31,1)*24>12.5,1,0.75))) -> 0.5 | K31: =IF(F31="Ausfall",6,IF(ISBLANK(H31),"",MOD(I31-H31,1)*24-J31)) -> 8 | L31: 720 | O31: =IFERROR(+MIN(IF(OR(H31="",I31=""),"",(MAX(,MIN(I31-(J31/24)+(H31>I31-(J31/24)),MAX(($CA$4>$CC$4),$CC$4))-MAX(H31,$CA$4))+MAX(,MIN(I31-(J31/24),MAX(($CA$4>$CC$4),$CC$4))-MAX(,$CA$4))*(H31>I31-(J31/24))+MAX(,MIN(I31-(J31/24)+(H31>I31-(J31/24)),MIN(($CA$4>$CC$4),$CC$4))-MAX(H31,))+MIN(I31-(J31/24),MIN(($CA$4>$CC$4),$CC$4))*(H31>I31-(J31/24)))*24),8),"") -> 8 | P31: =IFERROR(IF(H31<0.0451388888888889,IF(AND(WEEKDAY(B32)>0,WEEKDAY(B32)<6),0,IF(AND(WEEKDAY(B32)=7,H31<BW31),K31/24,IF(AND(WEEKDAY(B32)=7,H31>BW31),"24:00"-H31,IF(AND(WEEKDAY(B32)=6,BW31>H31),0,BW31)))*24),IF(AND(WEEKDAY(B31)>0,WEEKDAY(B31)<6),0,IF(AND(WEEKDAY(B31)=7,BX31="",H31<BW31),K31/24,IF(AND(WEEKDAY(B31)=7,H31>BW31),"24:00"-H31,IF(AND(WEEKDAY(B31)=6,BX32="",BW31<H31),BW31,0)))*24)),"") | Q31: =IFERROR(IF(H31<0.0451388888888889,IF(AND(WEEKDAY(B32)>1,WEEKDAY(B32)<7),0,IF(AND(WEEKDAY(B32)=1,H31<BW31),K31/24,IF(AND(WEEKDAY(B32)=1,H31>BW31),"24:00"-H31,IF(AND(WEEKDAY(B32)=7,BW31>H31),0,BW31)))*24),IF(AND(WEEKDAY(B31)>1,WEEKDAY(B31)<7),0,IF(AND(WEEKDAY(B31)=1,BX31="",H31<BW31),K31/24,IF(AND(WEEKDAY(B31)=1,H31>BW31),"24:00"-H31,IF(AND(WEEKDAY(B31)=7,BX32="",BW31<H31),BW31,0)))*24)),"") | R31: =IFERROR(IF(AND(BX31="",BX32=""),"",IF(AND(BX31="x",BX32="x"),K31,IF(BX31="x",IF(H31>BW31,"24:00"-H31,BW31-H31)*24,IF(AND(BX32="x",H31>I31),BW31*24,"")))),"") | X31: =IFERROR(IF(OR(F31="Urlaub",F31="Krank",F31="AZK"),8,IF(OR(F31="Urlaub 50%",F31="AZK 50%"),4,IF(AND(F31="",BX31="x"),8,K31))),"") -> 8 | BV31: =IF(L31="","",(L31/2-1)*2) -> 718 | BW31: =IFERROR(I31-(J31/24),"") -> 0.16666667 | BX31: =IF(ISERROR(VLOOKUP(B31,CB9:CB177,1,FALSE)),"","x") | BZ31: Fronleichnam | CB31: 43993
A32: =TEXT(B32,"TTT") -> #VALUE! | B32: =B31+1 -> #VALUE! | C32: =IF(H32="","",IF(OR(H32>=0.708333333333333,H32<0.125),"N","")) | J32: =IF(ISBLANK(H32),"",IF(MOD(I32-H32,1)*24<9,0.5,IF(MOD(I32-H32,1)*24>12.5,1,0.75))) | K32: =IF(F32="Ausfall",6,IF(ISBLANK(H32),"",MOD(I32-H32,1)*24-J32)) | O32: =IFERROR(+MIN(IF(OR(H32="",I32=""),"",(MAX(,MIN(I32-(J32/24)+(H32>I32-(J32/24)),MAX(($CA$4>$CC$4),$CC$4))-MAX(H32,$CA$4))+MAX(,MIN(I32-(J32/24),MAX(($CA$4>$CC$4),$CC$4))-MAX(,$CA$4))*(H32>I32-(J32/24))+MAX(,MIN(I32-(J32/24)+(H32>I32-(J32/24)),MIN(($CA$4>$CC$4),$CC$4))-MAX(H32,))+MIN(I32-(J32/24),MIN(($CA$4>$CC$4),$CC$4))*(H32>I32-(J32/24)))*24),8),"") | P32: =IFERROR(IF(H32<0.0451388888888889,IF(AND(WEEKDAY(B33)>0,WEEKDAY(B33)<6),0,IF(AND(WEEKDAY(B33)=7,H32<BW32),K32/24,IF(AND(WEEKDAY(B33)=7,H32>BW32),"24:00"-H32,IF(AND(WEEKDAY(B33)=6,BW32>H32),0,BW32)))*24),IF(AND(WEEKDAY(B32)>0,WEEKDAY(B32)<6),0,IF(AND(WEEKDAY(B32)=7,BX32="",H32<BW32),K32/24,IF(AND(WEEKDAY(B32)=7,H32>BW32),"24:00"-H32,IF(AND(WEEKDAY(B32)=6,BX33="",BW32<H32),BW32,0)))*24)),"") | Q32: =IFERROR(IF(H32<0.0451388888888889,IF(AND(WEEKDAY(B33)>1,WEEKDAY(B33)<7),0,IF(AND(WEEKDAY(B33)=1,H32<BW32),K32/24,IF(AND(WEEKDAY(B33)=1,H32>BW32),"24:00"-H32,IF(AND(WEEKDAY(B33)=7,BW32>H32),0,BW32)))*24),IF(AND(WEEKDAY(B32)>1,WEEKDAY(B32)<7),0,IF(AND(WEEKDAY(B32)=1,BX32="",H32<BW32),K32/24,IF(AND(WEEKDAY(B32)=1,H32>BW32),"24:00"-H32,IF(AND(WEEKDAY(B32)=7,BX33="",BW32<H32),BW32,0)))*24)),"") | R32: =IFERROR(IF(AND(BX32="",BX33=""),"",IF(AND(BX32="x",BX33="x"),K32,IF(BX32="x",IF(H32>BW32,"24:00"-H32,BW32-H32)*24,IF(AND(BX33="x",H32>I32),BW32*24,"")))),"") | X32: =IFERROR(IF(OR(F32="Urlaub",F32="Krank",F32="AZK"),8,IF(OR(F32="Urlaub 50%",F32="AZK 50%"),4,IF(AND(F32="",BX32="x"),8,K32))),"") | BV32: =IF(L32="","",(L32/2-1)*2) | BW32: =IFERROR(I32-(J32/24),"") | BX32: =IF(ISERROR(VLOOKUP(B32,CB9:CB177,1,FALSE)),"","x") | BZ32: Tag der Deutschen Einheit | CB32: 44107
A33: =TEXT(B33,"TTT") -> #VALUE! | B33: =B32+1 -> #VALUE! | C33: =IF(H33="","",IF(OR(H33>=0.708333333333333,H33<0.125),"N","")) | J33: =IF(ISBLANK(H33),"",IF(MOD(I33-H33,1)*24<9,0.5,IF(MOD(I33-H33,1)*24>12.5,1,0.75))) | K33: =IF(F33="Ausfall",6,IF(ISBLANK(H33),"",MOD(I33-H33,1)*24-J33)) | O33: =IFERROR(+MIN(IF(OR(H33="",I33=""),"",(MAX(,MIN(I33-(J33/24)+(H33>I33-(J33/24)),MAX(($CA$4>$CC$4),$CC$4))-MAX(H33,$CA$4))+MAX(,MIN(I33-(J33/24),MAX(($CA$4>$CC$4),$CC$4))-MAX(,$CA$4))*(H33>I33-(J33/24))+MAX(,MIN(I33-(J33/24)+(H33>I33-(J33/24)),MIN(($CA$4>$CC$4),$CC$4))-MAX(H33,))+MIN(I33-(J33/24),MIN(($CA$4>$CC$4),$CC$4))*(H33>I33-(J33/24)))*24),8),"") | P33: =IFERROR(IF(H33<0.0451388888888889,IF(AND(WEEKDAY(B34)>0,WEEKDAY(B34)<6),0,IF(AND(WEEKDAY(B34)=7,H33<BW33),K33/24,IF(AND(WEEKDAY(B34)=7,H33>BW33),"24:00"-H33,IF(AND(WEEKDAY(B34)=6,BW33>H33),0,BW33)))*24),IF(AND(WEEKDAY(B33)>0,WEEKDAY(B33)<6),0,IF(AND(WEEKDAY(B33)=7,BX33="",H33<BW33),K33/24,IF(AND(WEEKDAY(B33)=7,H33>BW33),"24:00"-H33,IF(AND(WEEKDAY(B33)=6,BX34="",BW33<H33),BW33,0)))*24)),"") | Q33: =IFERROR(IF(H33<0.0451388888888889,IF(AND(WEEKDAY(B34)>1,WEEKDAY(B34)<7),0,IF(AND(WEEKDAY(B34)=1,H33<BW33),K33/24,IF(AND(WEEKDAY(B34)=1,H33>BW33),"24:00"-H33,IF(AND(WEEKDAY(B34)=7,BW33>H33),0,BW33)))*24),IF(AND(WEEKDAY(B33)>1,WEEKDAY(B33)<7),0,IF(AND(WEEKDAY(B33)=1,BX33="",H33<BW33),K33/24,IF(AND(WEEKDAY(B33)=1,H33>BW33),"24:00"-H33,IF(AND(WEEKDAY(B33)=7,BX34="",BW33<H33),BW33,0)))*24)),"") | R33: =IFERROR(IF(AND(BX33="",BX34=""),"",IF(AND(BX33="x",BX34="x"),K33,IF(BX33="x",IF(H33>BW33,"24:00"-H33,BW33-H33)*24,IF(AND(BX34="x",H33>I33),BW33*24,"")))),"") | X33: =IFERROR(IF(OR(F33="Urlaub",F33="Krank",F33="AZK"),8,IF(OR(F33="Urlaub 50%",F33="AZK 50%"),4,IF(AND(F33="",BX33="x"),8,K33))),"") | BV33: =IF(L33="","",(L33/2-1)*2) | BW33: =IFERROR(I33-(J33/24),"") | BX33: =IF(ISERROR(VLOOKUP(B33,CB9:CB177,1,FALSE)),"","x") | BZ33: Allerheiligen | CB33: 44136
A34: =TEXT(B34,"TTT") -> #VALUE! | B34: =B33+1 -> #VALUE! | C34: =IF(H34="","",IF(OR(H34>=0.708333333333333,H34<0.125),"N","")) | J34: =IF(ISBLANK(H34),"",IF(MOD(I34-H34,1)*24<9,0.5,IF(MOD(I34-H34,1)*24>12.5,1,0.75))) | K34: =IF(F34="Ausfall",6,IF(ISBLANK(H34),"",MOD(I34-H34,1)*24-J34)) | O34: =IFERROR(+MIN(IF(OR(H34="",I34=""),"",(MAX(,MIN(I34-(J34/24)+(H34>I34-(J34/24)),MAX(($CA$4>$CC$4),$CC$4))-MAX(H34,$CA$4))+MAX(,MIN(I34-(J34/24),MAX(($CA$4>$CC$4),$CC$4))-MAX(,$CA$4))*(H34>I34-(J34/24))+MAX(,MIN(I34-(J34/24)+(H34>I34-(J34/24)),MIN(($CA$4>$CC$4),$CC$4))-MAX(H34,))+MIN(I34-(J34/24),MIN(($CA$4>$CC$4),$CC$4))*(H34>I34-(J34/24)))*24),8),"") | P34: =IFERROR(IF(H34<0.0451388888888889,IF(AND(WEEKDAY(B35)>0,WEEKDAY(B35)<6),0,IF(AND(WEEKDAY(B35)=7,H34<BW34),K34/24,IF(AND(WEEKDAY(B35)=7,H34>BW34),"24:00"-H34,IF(AND(WEEKDAY(B35)=6,BW34>H34),0,BW34)))*24),IF(AND(WEEKDAY(B34)>0,WEEKDAY(B34)<6),0,IF(AND(WEEKDAY(B34)=7,BX34="",H34<BW34),K34/24,IF(AND(WEEKDAY(B34)=7,H34>BW34),"24:00"-H34,IF(AND(WEEKDAY(B34)=6,BX35="",BW34<H34),BW34,0)))*24)),"") | Q34: =IFERROR(IF(H34<0.0451388888888889,IF(AND(WEEKDAY(B35)>1,WEEKDAY(B35)<7),0,IF(AND(WEEKDAY(B35)=1,H34<BW34),K34/24,IF(AND(WEEKDAY(B35)=1,H34>BW34),"24:00"-H34,IF(AND(WEEKDAY(B35)=7,BW34>H34),0,BW34)))*24),IF(AND(WEEKDAY(B34)>1,WEEKDAY(B34)<7),0,IF(AND(WEEKDAY(B34)=1,BX34="",H34<BW34),K34/24,IF(AND(WEEKDAY(B34)=1,H34>BW34),"24:00"-H34,IF(AND(WEEKDAY(B34)=7,BX35="",BW34<H34),BW34,0)))*24)),"") | R34: =IFERROR(IF(AND(BX34="",BX35=""),"",IF(AND(BX34="x",BX35="x"),K34,IF(BX34="x",IF(H34>BW34,"24:00"-H34,BW34-H34)*24,IF(AND(BX35="x",H34>I34),BW34*24,"")))),"") | BV34: =IF(L34="","",(L34/2-1)*2) | BW34: =IFERROR(I34-(J34/24),"") | BX34: =IF(ISERROR(VLOOKUP(B34,CB9:CB177,1,FALSE)),"","x") | BZ34: 1. Weihnachtsfeiertag | CB34: 44190
A35: =TEXT(B35,"TTT") -> #VALUE! | B35: =B34+1 -> #VALUE! | C35: =IF(H35="","",IF(OR(H35>=0.708333333333333,H35<0.125),"N","")) | J35: =IF(ISBLANK(H35),"",IF(MOD(I35-H35,1)*24<9,0.5,IF(MOD(I35-H35,1)*24>12.5,1,0.75))) | K35: =IF(F35="Ausfall",6,IF(ISBLANK(H35),"",MOD(I35-H35,1)*24-J35)) | O35: =IFERROR(+MIN(IF(OR(H35="",I35=""),"",(MAX(,MIN(I35-(J35/24)+(H35>I35-(J35/24)),MAX(($CA$4>$CC$4),$CC$4))-MAX(H35,$CA$4))+MAX(,MIN(I35-(J35/24),MAX(($CA$4>$CC$4),$CC$4))-MAX(,$CA$4))*(H35>I35-(J35/24))+MAX(,MIN(I35-(J35/24)+(H35>I35-(J35/24)),MIN(($CA$4>$CC$4),$CC$4))-MAX(H35,))+MIN(I35-(J35/24),MIN(($CA$4>$CC$4),$CC$4))*(H35>I35-(J35/24)))*24),8),"") | P35: =IFERROR(IF(H35<0.0451388888888889,IF(AND(WEEKDAY(B36)>0,WEEKDAY(B36)<6),0,IF(AND(WEEKDAY(B36)=7,H35<BW35),K35/24,IF(AND(WEEKDAY(B36)=7,H35>BW35),"24:00"-H35,IF(AND(WEEKDAY(B36)=6,BW35>H35),0,BW35)))*24),IF(AND(WEEKDAY(B35)>0,WEEKDAY(B35)<6),0,IF(AND(WEEKDAY(B35)=7,BX35="",H35<BW35),K35/24,IF(AND(WEEKDAY(B35)=7,H35>BW35),"24:00"-H35,IF(AND(WEEKDAY(B35)=6,BX36="",BW35<H35),BW35,0)))*24)),"") | Q35: =IFERROR(IF(H35<0.0451388888888889,IF(AND(WEEKDAY(B36)>1,WEEKDAY(B36)<7),0,IF(AND(WEEKDAY(B36)=1,H35<BW35),K35/24,IF(AND(WEEKDAY(B36)=1,H35>BW35),"24:00"-H35,IF(AND(WEEKDAY(B36)=7,BW35>H35),0,BW35)))*24),IF(AND(WEEKDAY(B35)>1,WEEKDAY(B35)<7),0,IF(AND(WEEKDAY(B35)=1,BX35="",H35<BW35),K35/24,IF(AND(WEEKDAY(B35)=1,H35>BW35),"24:00"-H35,IF(AND(WEEKDAY(B35)=7,BX36="",BW35<H35),BW35,0)))*24)),"") | R35: =IFERROR(IF(AND(BX35="",BX36=""),"",IF(AND(BX35="x",BX36="x"),K35,IF(BX35="x",IF(H35>BW35,"24:00"-H35,BW35-H35)*24,IF(AND(BX36="x",H35>I35),BW35*24,"")))),"") | X35: =IFERROR(IF(OR(F35="Urlaub",F35="Krank",F35="AZK"),8,IF(OR(F35="Urlaub 50%",F35="AZK 50%"),4,IF(AND(F35="",BX35="x"),8,K35))),"") | BV35: =IF(L35="","",(L35/2-1)*2) | BW35: =IFERROR(I35-(J35/24),"") | BX35: =IF(ISERROR(VLOOKUP(B35,CB9:CB177,1,FALSE)),"","x") | BZ35: 2. Weihnachtsfeiertag | CB35: 44191
A36: =TEXT(B36,"TTT") -> #VALUE! | B36: =IF(AND(MOD(I5,4)=0,H5=2),B35+1,IF(H5<>2,B35+1,"")) -> #VALUE! | C36: =IF(H36="","",IF(OR(H36>=0.708333333333333,H36<0.125),"N","")) | J36: =IF(ISBLANK(H36),"",IF(MOD(I36-H36,1)*24<9,0.5,IF(MOD(I36-H36,1)*24>12.5,1,0.75))) | K36: =IF(F36="Ausfall",6,IF(ISBLANK(H36),"",MOD(I36-H36,1)*24-J36)) | O36: =IFERROR(+MIN(IF(OR(H36="",I36=""),"",(MAX(,MIN(I36-(J36/24)+(H36>I36-(J36/24)),MAX(($CA$4>$CC$4),$CC$4))-MAX(H36,$CA$4))+MAX(,MIN(I36-(J36/24),MAX(($CA$4>$CC$4),$CC$4))-MAX(,$CA$4))*(H36>I36-(J36/24))+MAX(,MIN(I36-(J36/24)+(H36>I36-(J36/24)),MIN(($CA$4>$CC$4),$CC$4))-MAX(H36,))+MIN(I36-(J36/24),MIN(($CA$4>$CC$4),$CC$4))*(H36>I36-(J36/24)))*24),8),"") | P36: =IFERROR(IF(H36<0.0451388888888889,IF(AND(WEEKDAY(B37)>0,WEEKDAY(B37)<6),0,IF(AND(WEEKDAY(B37)=7,H36<BW36),K36/24,IF(AND(WEEKDAY(B37)=7,H36>BW36),"24:00"-H36,IF(AND(WEEKDAY(B37)=6,BW36>H36),0,BW36)))*24),IF(AND(WEEKDAY(B36)>0,WEEKDAY(B36)<6),0,IF(AND(WEEKDAY(B36)=7,BX36="",H36<BW36),K36/24,IF(AND(WEEKDAY(B36)=7,H36>BW36),"24:00"-H36,IF(AND(WEEKDAY(B36)=6,BX37="",BW36<H36),BW36,0)))*24)),"") | Q36: =IFERROR(IF(H36<0.0451388888888889,IF(AND(WEEKDAY(B37)>1,WEEKDAY(B37)<7),0,IF(AND(WEEKDAY(B37)=1,H36<BW36),K36/24,IF(AND(WEEKDAY(B37)=1,H36>BW36),"24:00"-H36,IF(AND(WEEKDAY(B37)=7,BW36>H36),0,BW36)))*24),IF(AND(WEEKDAY(B36)>1,WEEKDAY(B36)<7),0,IF(AND(WEEKDAY(B36)=1,BX36="",H36<BW36),K36/24,IF(AND(WEEKDAY(B36)=1,H36>BW36),"24:00"-H36,IF(AND(WEEKDAY(B36)=7,BX37="",BW36<H36),BW36,0)))*24)),"") | R36: =IFERROR(IF(AND(BX36="",BX37=""),"",IF(AND(BX36="x",BX37="x"),K36,IF(BX36="x",IF(H36>BW36,"24:00"-H36,BW36-H36)*24,IF(AND(BX37="x",H36>I36),BW36*24,"")))),"") | X36: =IFERROR(IF(OR(F36="Urlaub",F36="Krank",F36="AZK"),8,IF(OR(F36="Urlaub 50%",F36="AZK 50%"),4,IF(AND(F36="",BX36="x"),8,K36))),"") | BV36: =IF(L36="","",(L36/2-1)*2) | BW36: =IFERROR(I36-(J36/24),"") | BX36: =IF(ISERROR(VLOOKUP(B36,CB9:CB177,1,FALSE)),"","x") | BY36: =B35+1 -> #VALUE!
